Workbook
Name \A: #REF!
Name \aa: #REF!
Name \aaa: #REF!
Name \aaaa: #REF!
Name \activa: #REF!
Name \alcant: #REF!
Name \almace: #REF!
Name \b: #REF!
Name \bb: #REF!
Name \bbb: #REF!
Name \bbbb: #REF!
Name \bbbbb: #REF!
Name \bombe: #REF!
Name \capt: #REF!
Name \cond: #REF!
Name \cruda: #REF!
Name \d: #REF!
Name \Dato: #REF!
Name \dd: #REF!
Name \desa: #REF!
Name \Diag: #REF!
Name \e: #REF!
Name \lagu: #REF!
Name \m: #REF!
Name \medido: #REF!
Name \Metas: #REF!
Name \mm: #REF!
Name \mmm: #REF!
Name \mmmm: #REF!
Name \n: #REF!
Name \nn: #REF!
Name \nnn: #REF!
Name \nnnn: #REF!
Name \oferta: #REF!
Name \Pasiva: #REF!
Name \pobla: #REF!
Name \pre: #REF!
Name \prima: #REF!
Name \Q: #REF!
Name \QQ: #REF!
Name \QQQ: #REF!
Name \QQQQ: #REF!
Name \r: #REF!
Name \rr: #REF!
Name \rrrr: #REF!
Name \RRRRR: #REF!
Name \TOTAL: #REF!
Name \trata: #REF!
Name \tribu: #REF!
Name \tt: #REF!
Name \ttt: #REF!
Name \tttt: #REF!
Name \UsuarP: #REF!
Name __PP1: '[4]Red 12Piletas'!$E$99
Name __PP1: '[4]Red 12Piletas'!$E$99
Name __PP1: '[4]Red 12Piletas'!$E$99
Name __PP1: '[4]Red 12Piletas'!$E$99
Name __PP1: '[5]Red 12Piletas'!$E$99
Name __PP1: '[5]Red 12Piletas'!$E$99
Name __PP1: '[5]Red 12Piletas'!$E$99

Sheet 1.1 MIT. AMB.
A1: METRADOS SISTEMA DE AGUA POTABLE
A2: "CREACION DEL SERVICIO DE AGUA POTABLE RURAL Y CREACION DEL SERVICIO DE ALCANTARILLADO U OTRAS FORMAS DE DISPOSICION SANITARIA DE EXCRETAS EN EL SECTOR NUEVA ESPERANZA DE LA CC.NN. BAJO PITOCUNA DISTRITO DE RIO NEGRO, PROVINCIA DE SATIPO, DEPARTAMENTO DE JUNIN"
A3: OBRAS PROVISIONALES
A5: PARTIDA | B5: DESCRIPCION | C5: UNID. | D5: VECES | E5: LONG. | F5: ANCHO | G5: ALTURA | H5: SUB-TOTAL | I5: TOTAL
A6: 1.01 | B6: OBRAS PROVISIONALES
A7: =A6 & ".01" -> 1.01.01 | B7: CARTEL DE IDENTIFICACION DE OBRA DE 3.60m x 2.40m | C7: UND | H7: 1 | I7: =+H7 -> 1
A9: =A6 & ".02" -> 1.01.02 | B9: MOVILIZACION Y DESMOVILIZACION DE EQUIPOS Y MAQUINARIA PARA LA OBRA | C9: GLB | H9: 1 | I9: =+H9 -> 1

Sheet 1.2 CAP. T- LADERA
A1: HOJA DE METRADOS DEL SISTEMA DE AGUA POTABLE
A3: PROYECTO: | B3: "CREACION DEL SERVICIO DE AGUA POTABLE RURAL Y CREACION DEL SERVICIO DE ALCANTARILLADO U OTRAS FORMAS DE DISPOSICION SANITARIA DE EXCRETAS EN EL SECTOR NUEVA ESPERANZA DE LA CC.NN. BAJO PITOCUNA DISTRITO DE RIO NEGRO, PROVINCIA DE SATIPO, DEPARTAMENTO DE JUNIN"
A5: CAPTACION TIPO LADERA "PROSPERO"
A23: PARTIDA | B23: DESCRIPCION | C23: UNI | D23: CANT | E23: LARGO | F23: ANCHO | G23: ALTURA | H23: SUB-TOTAL | I23: TOTAL
A24: 01.02 | B24: CAPTACION DE LADERA - "PROSPERO" CONSTRUCCION (01 UND)
A25: =A$24 & ".01" -> 01.02.01 | B25: ESTRUCTURAS
A26: =A$25 & ".01" -> 01.02.01.01 | B26: TRABAJOS PRELIMINARES
A27: =A$26 & ".01" -> 01.02.01.01.01 | B27: LIMPIEZA DE TERRENO Y DESBROCE DE TERRENO MANUAL | C27: m2 | I27: =+H28 -> 37.0368
B28: Captación | D28: 1 | E28: 5.76 | F28: 6.43 | H28: =+F28*E28*D28 -> 37.0368
A29: =A$26 & ".02" -> 01.02.01.01.02 | B29: TRAZO Y REPLANTEO PRELIMINAR | C29: m2 | I29: =+H30 -> 37.0368
B30: Captación | D30: 1 | E30: =+E28 -> 5.76 | F30: =F28 -> 6.43 | H30: =+F30*E30*D30 -> 37.0368
A31: =A$26 & ".03" -> 01.02.01.01.03 | B31: TRAZO Y REPLANTEO DURANTE EL PROCESO | C31: m2 | I31: =SUM(H32:H34) -> 6.3025
B32: Aletas de protección | D32: 1 | E32: área | F32: 3.9 | H32: =PRODUCT(D32:G32) -> 3.9
B33: Cámara húmeda | D33: 1 | E33: 1.3 | F33: 1.3 | H33: =PRODUCT(D33:G33) -> 1.69
B34: Cámara seca | D34: 1 | E34: 0.95 | F34: 0.75 | H34: =PRODUCT(D34:G34) -> 0.7125
A36: =A$25 & ".02" -> 01.02.01.02 | B36: MOVIMIENTO DE TIERRAS
A37: =A$36 & ".01" -> 01.02.01.02.01 | B37: EXCAVACION MANUAL EN TERRENO NORMAL | C37: m3 | I37: =SUM(H38) -> 16.5
B38: Area de perfil y seccion | D38: 1 | E38: volumen | G38: 16.5 | H38: =+PRODUCT(D38:G38) -> 16.5
A41: =A$36 & ".02" -> 01.02.01.02.02 | B41: NIVELACION INTERIOR Y APISONADO (MANUAL) | C41: m2 | I41: =SUM(H42:H44) -> 6.3025
B42: Aletas de protección | D42: 1 | E42: área | F42: 3.9 | H42: =F42*D42 -> 3.9
B43: Cámara húmeda | D43: 1 | E43: 1.3 | F43: 1.3 | H43: =+F43*E43*D43 -> 1.69
B44: Cámara seca | D44: 1 | E44: 0.95 | F44: 0.75 | H44: =+F44*E44*D44 -> 0.7125
A46: =A$36 & ".03" -> 01.02.01.02.03 | B46: RELLENO COMPACTADO CON MATERIAL PROPIO SELECCIONADO | C46: m3 | I46: =SUM(H47) -> 4.5
D47: 1 | E47: volumen | G47: 4.5 | H47: =+PRODUCT(D47:G47) -> 4.5
A49: =A$36 & ".04" -> 01.02.01.02.04 | B49: ACARREO DE MAT. PARA RELLENO EN CAPTACIÓN | C49: m3 | I49: =+H50+H51 -> 14.625
B50: Excavacion - Esponjamiento 20% | D50: 1 | E50: 1.2 | F50: Volumen | G50: =I37 -> 16.5 | H50: =PRODUCT(D50:G50) -> 19.8
B51: Relleno - Compactacion | D51: -1 | E51: 1.15 | F51: Volumen | G51: =I46 -> 4.5 | H51: =PRODUCT(D51:G51) -> -5.175
A52: =A$25 & ".03" -> 01.02.01.03 | B52: OBRAS DE CONCRETO SIMPLE
A53: =A$52 & ".01" -> 01.02.01.03.01 | B53: CONCRETO SIMPLE F'C=100 KG/CM2, PARA SOLADO e=10cm | C53: m2 | I53: =SUM(H54:H59) -> 3.3825
B54: Alas de protección | D54: 2 | E54: 2 | F54: 0.25 | H54: =+D54*E54*F54 -> 1
B55: Pantalla de captación | D55: 1 | E55: 1.2 | F55: 0.2 | H55: =+D55*E55*F55 -> 0.24
B56: Piso de la cámara Húmeda | D56: 1 | E56: 0.9 | F56: 0.9 | H56: =+D56*E56*F56 -> 0.81
B57: Cimiento de la cámara Húmeda | D57: 2 | E57: 1.1 | F57: 0.2 | H57: =+D57*E57*F57 -> 0.44
D58: 1 | E58: 0.9 | F58: 0.2 | H58: =+D58*E58*F58 -> 0.18
B59: Cámara Seca | D59: 1 | E59: 0.75 | F59: 0.95 | H59: =+D59*E59*F59 -> 0.7125
A61: =A$52 & ".02" -> 01.02.01.03.02 | B61: CONCRETO f'c=140 kg/cm2 + 30 %PM. | C61: m3 | I61: =SUM(H62:H63) -> 1.946
B62: Dado asentado 0.50x0.50m | D62: 1 | E62: 0.5 | F62: 0.5 | G62: 0.2 | H62: =+D62*E62*F62*G62 -> 0.05
B63: En la base de la zona de afloramiento | D63: 1 | E63: área | F63: 0.79 | G63: 2.4 | H63: =+F63*D63*G63 -> 1.896
A65: =A$52 & ".03" -> 01.02.01.03.03 | B65: CONCRETO f'c=140 kg/cm2, EN DADOS | C65: m3 | I65: =+H66 -> 0.018
B66: Dado móvil de tubería de rebose y limpia | D66: 1 | E66: 0.3 | F66: 0.3 | G66: 0.2 | H66: =+PRODUCT(D66:G66) -> 0.018
...

Sheet 1.2 MET. DE ACERO
B2: METRADO DE ACERO DE REFUERZO
B3: PROYECTO | D3: "CREACION DEL SERVICIO DE AGUA POTABLE RURAL Y CREACION DEL SERVICIO DE ALCANTARILLADO U OTRAS FORMAS DE DISPOSICION SANITARIA DE EXCRETAS EN EL SECTOR NUEVA ESPERANZA DE LA CC.NN. BAJO PITOCUNA DISTRITO DE RIO NEGRO, PROVINCIA DE SATIPO, DEPARTAMENTO DE JUNIN" | P3: ESTRUCTURA :
P4: CAPTACIÓN TIPO LADERA
P5: CÁMARA DE FILTROS
B7: ITEM | C7: DESCRIPCION | D7: FORMA | J7: Ø (Pulg) | K7: LONG. (m) | L7: # BARRAS | M7: # ELEMEN. | N7: LARGO TOTAL | S7: OBSERV.
L8: ELEMENTO | M8: ELEMENTO | N8: 0.25 | O8: 0.375 | P8: 0.5 | Q8: 0.625 | R8: 0.75
C9: Acero cimiento - vertical
B12: 1 | G12: 0.63 | J12: 0.375 | K12: =SUM(D9:I14) -> 0.72 | L12: 10 | M12: 2 | N12: =IF(J12=1/4,L12*K12*M12,"-") -> - | O12: =IF(J12=3/8,K12*L12*M12,"-") -> 14.4 | P12: =IF(J12=1/2,L12*K12*M12,"-") -> - | Q12: =IF(J12=5/8,L12*K12*M12,"-") -> - | R12: =IF(J12=3/4,K12*L12,"-") -> -
F13: 0.09
C15: Acero cimiento y muro - horizontal
B16: 2 | D16: 0.15 | F16: 2.03 | J16: 0.375 | K16: =SUM(D15:I17) -> 2.18 | L16: 6 | M16: 2 | N16: =IF(J16=1/4,L16*K16*M16,"-") -> - | O16: =IF(J16=3/8,K16*L16*M16,"-") -> 26.16 | P16: =IF(J16=1/2,L16*K16*M16,"-") -> - | Q16: =IF(J16=5/8,L16*K16*M16,"-") -> - | R16: =IF(J16=3/4,K16*L16,"-") -> -
C18: Acero muro - vertical | F18: 0.15
F20: 1.51
B21: 3 | J21: 0.375 | K21: =SUM(D18:I23) -> 1.81 | L21: 10 | M21: 2 | N21: =IF(J21=1/4,L21*K21*M21,"-") -> - | O21: =IF(J21=3/8,K21*L21*M21,"-") -> 36.2 | P21: =IF(J21=1/2,L21*K21*M21,"-") -> - | Q21: =IF(J21=5/8,L21*K21*M21,"-") -> - | R21: =IF(J21=3/4,K21*L21,"-") -> -
G23: 0.15
C24: Acero en losa - transversal
F25: promedio
F26: 2.87
B27: 4 | J27: 0.375 | K27: =SUM(D24:I29) -> 3.17 | L27: 7 | M27: 1 | N27: =IF(J27=1/4,L27*K27*M27,"-") -> - | O27: =IF(J27=3/8,K27*L27*M27,"-") -> 22.19 | P27: =IF(J27=1/2,L27*K27*M27,"-") -> - | Q27: =IF(J27=5/8,L27*K27*M27,"-") -> - | R27: =IF(J27=3/4,K27*L27,"-") -> -
E28: 0.15 | H28: 0.15
C30: Acero en losa - longitudinal
F31: promedio
F32: 1.05
B33: 5 | J33: 0.375 | K33: =SUM(D30:I35) -> 1.35 | L33: 18 | M33: 1 | N33: =IF(J33=1/4,L33*K33*M33,"-") -> - | O33: =IF(J33=3/8,K33*L33*M33,"-") -> 24.3 | P33: =IF(J33=1/2,L33*K33*M33,"-") -> - | Q33: =IF(J33=5/8,L33*K33*M33,"-") -> - | R33: =IF(J33=3/4,K33*L33,"-") -> -
E34: 0.15 | H34: 0.15
J36: LONGITUD TOTAL (M) | N36: =SUM(N9:N29) -> 0 | O36: =SUM(O9:O35) -> 123.25 | P36: =SUM(P9:P29) -> 0 | Q36: =SUM(Q9:Q29) -> 0 | R36: =SUM(R9:R29) -> 0
J37: PESO x M.L (kg) | N37: 0.22 | O37: 0.56 | P37: 0.994 | Q37: 1.552 | R37: 2.235
J38: SUB TOTAL | N38: =N36*N37 -> 0 | O38: =O36*O37 -> 69.02 | P38: =P36*P37 -> 0 | Q38: =Q36*Q37 -> 0 | R38: =R36*R37 -> 0
J39: N° DE UNIDADES | M39: 1
J40: PESO TOTAL (KG) | M40: =SUM(N38:S38)*M39 -> 69.02
B43: METRADO DE ACERO DE REFUERZO
B44: PROYECTO | D44: "CREACION DEL SERVICIO DE AGUA POTABLE RURAL Y CREACION DEL SERVICIO DE ALCANTARILLADO U OTRAS FORMAS DE DISPOSICION SANITARIA DE EXCRETAS EN EL SECTOR NUEVA ESPERANZA DE LA CC.NN. BAJO PITOCUNA DISTRITO DE RIO NEGRO, PROVINCIA DE SATIPO, DEPARTAMENTO DE JUNIN" | P44: ESTRUCTURA :
P45: CAPTACIÓN TIPO LADERA
P46: CÁMARA HÚMEDA
B48: ITEM | C48: DESCRIPCION | D48: FORMA | J48: Ø (Pulg) | K48: LONG. (m) | L48: # BARRAS | M48: # ELEMEN. | N48: LARGO TOTAL | S48: OBSERV.
L49: ELEMENTO | M49: ELEMENTO | N49: 0.25 | O49: 0.375 | P49: 0.5 | Q49: 0.625 | R49: 0.75
C50: Acero cimiento de muro de entrada - vertical
B53: 1 | G53: 0.63 | J53: 0.375 | K53: =SUM(D50:I55) -> 0.69 | L53: 7 | M53: 1 | N53: =IF(J53=1/4,L53*K53*M53,"-") -> - | O53: =IF(J53=3/8,K53*L53*M53,"-") -> 4.83 | P53: =IF(J53=1/2,L53*K53*M53,"-") -> - | Q53: =IF(J53=5/8,L53*K53*M53,"-") -> - | R53: =IF(J53=3/4,K53*L53,"-") -> -
F54: 0.06
C56: Acero cimiento de muro de entrada - horizontal
...

Sheet 1.3 L-COND.
A2: HOJA DE METRADOS DE AGUA POTABLE
A3: "CREACION DEL SERVICIO DE AGUA POTABLE RURAL Y CREACION DEL SERVICIO DE ALCANTARILLADO U OTRAS FORMAS DE DISPOSICION SANITARIA DE EXCRETAS EN EL SECTOR NUEVA ESPERANZA DE LA CC.NN. BAJO PITOCUNA DISTRITO DE RIO NEGRO, PROVINCIA DE SATIPO, DEPARTAMENTO DE JUNIN"
A4: LINEA DE CONDUCCIÓN
B6: Zanja Tipica | C6: =+C8&" x "&C7&" m" -> 0.5 x 0.7 m | D6: normal | E6: MANGUERA HDPE - 1 1/2"
B7: Altura | C7: 0.7 | D7: m
B8: Ancho | C8: 0.5 | D8: m
B9: Cama de Apoyo | C9: 0.1 | D9: m
B10: Capas de relleno con material propio | C10: =C7-C9 -> 0.6 | D10: m
A12: PARTIDA | B12: DESCRIPCION | C12: UNIDAD | D12: VECES | E12: LONGITUD | F12: ANCHO | G12: ALTURA | H12: SUB-TOTAL | I12: TOTAL
A13: =+"01.03" -> 01.03 | B13: =A4&" L= "&E17&"m" -> LINEA DE CONDUCCIÓN L= 139.7m | E13: =SUM(E14:E14) -> 139.7
B14: MANGUERA HDPE Ø 1 1/2" PN-8 TERRENO SUELTOS | C14: ML | D14: 1 | E14: 139.7
A16: =A$13 & ".01" -> 01.03.01 | B16: TRABAJOS PRELIMINARES
A17: =A$16 & ".01" -> 01.03.01.01 | B17: LIMPIEZA Y DESBROCE DE TERRENO MANUAL | C17: ML | D17: 1 | E17: =E13 -> 139.7 | H17: =+ROUND(PRODUCT(D17:G17),2) -> 139.7 | I17: =+H17 -> 139.7
A18: =A$16 & ".02" -> 01.03.01.02 | B18: TRAZO Y REPLANTEO PRELIMINAR EN LINEAS Y REDES | C18: ML | D18: 1 | E18: =E13 -> 139.7 | H18: =+ROUND(PRODUCT(D18:G18),2) -> 139.7 | I18: =+H18 -> 139.7
A19: =A$16 & ".03" -> 01.03.01.03 | B19: TRAZO Y REPLANTEO DURANTE EL PROCESO DE EJECUCION EN LINEAS Y REDES | C19: ML | D19: 1 | E19: =E13 -> 139.7 | H19: =+ROUND(PRODUCT(D19:G19),2) -> 139.7 | I19: =+H19 -> 139.7
A21: =A$13 & ".02" -> 01.03.02 | B21: MOVIMIENTO DE TIERRAS
A22: =$A$21 & ".01" -> 01.03.02.01 | B22: EXCAVACION MANUAL EN TERRENO SUELTO DE ZANJA DE 0.40 x 0.30 m P/MANGUERA HDPE | C22: ML | D22: 1 | E22: =E14 -> 139.7 | H22: =+ROUND(PRODUCT(D22:G22),2) -> 139.7 | I22: =+H22 -> 139.7
A23: =$A$21 & ".02" -> 01.03.02.02 | B23: RELLENO DE ZANJA, CON MAT. PROPIO, E=0.40m A=0.30m P/MANGUERA HDPE | C23: ML | D23: 1 | E23: =+E13 -> 139.7 | H23: =+ROUND(PRODUCT(D23:G23),2) -> 139.7 | I23: =+H23 -> 139.7
A24: =$A$21 & ".03" -> 01.03.02.03 | B24: ACARREO Y ELIMINACION DE MAT. EXCEDENTE Dmax=30 m | C24: M3 | H24: =SUM(H25:H26) -> 3.31 | I24: =+H24 -> 3.31
B25: Excavacion - Esponjamiento 25% terreno herbaceo | D25: 1.25 | E25: =E13 -> 139.7 | F25: 0.4 | G25: 0.3 | H25: =+ROUND(PRODUCT(D25:G25),2) -> 20.96
B26: Relleno | D26: =-1/0.95 -> -1.0526316 | E26: =+I22 -> 139.7 | F26: =+F25 -> 0.4 | G26: =G25 -> 0.3 | H26: =+ROUND(PRODUCT(D26:G26),2) -> -17.65
A28: =A$13 & ".03" -> 01.03.03 | B28: SUMINISTRO E INSTALACION DE TUBERIAS
A29: =A28 & ".01" -> 01.03.03.01 | B29: SUMINISTRO E INSTALACION DE MANGUERA HDPE NTP - ISO 4427: 2008 PE 80, PN=10, ø=44.4mm | C29: ML | D29: 1 | E29: =SUM(E14:E14) -> 139.7 | H29: =+ROUND(PRODUCT(D29:G29),2) -> 139.7 | I29: =+H29 -> 139.7
A31: =A$13 & ".04" -> 01.03.04 | B31: SUMINISTRO E INSTALACION DE ACCESORIOS
A32: =A31 & ".01" -> 01.03.04.01 | B32: SUMINISTRO E INSTALACION DE UNION ENLACE P/MANG. HDPE, PN-8 ø=44.4mm | C32: UND | D32: 1 | H32: =+ROUND(PRODUCT(D32:G32),2) -> 1 | I32: =+H32 -> 1
A34: =A$13 & ".05" -> 01.03.05 | B34: PRUEBA HIDRAULICA
A35: =A34 &".01" -> 01.03.05.01 | B35: PRUEBA HIDRÁULICA Y DESINFECCIÓN DE LA MANGUERA HDPE | C35: ML | D35: 1 | E35: =SUM(E14:E14) -> 139.7 | H35: =+ROUND(PRODUCT(D35:G35),2) -> 139.7 | I35: =+H35 -> 139.7

Sheet 1.4 RESERV. 5M3
A2: HOJA DE METRADOS DE SISTEMA DE AGUA POTABLE
A3: "CREACION DEL SERVICIO DE AGUA POTABLE RURAL Y CREACION DEL SERVICIO DE ALCANTARILLADO U OTRAS FORMAS DE DISPOSICION SANITARIA DE EXCRETAS EN EL SECTOR NUEVA ESPERANZA DE LA CC.NN. BAJO PITOCUNA DISTRITO DE RIO NEGRO, PROVINCIA DE SATIPO, DEPARTAMENTO DE JUNIN"
A5: RESERVORIO CUADRADO APOYADO DE V=5 m3
A25: PARTIDA | B25: DESCRIPCION | C25: UNID. | D25: VECES | E25: LONG. | F25: ANCHO/AREA | G25: ALTURA | H25: SUB-TOTAL | I25: TOTAL
A26: 01.04 | B26: =+A5 -> RESERVORIO CUADRADO APOYADO DE V=5 m3 | D26: 1
A27: =A$26 & ".01" -> 01.04.01 | B27: ESTRUCTURAS
A28: =A$27 & ".01" -> 01.04.01.01 | B28: TRABAJOS PRELIMINARES
A30: =A$28 & ".01" -> 01.04.01.01.01 | B30: LIMPIEZA Y DESBROCE DE TERRENO MANUAL | C30: m2 | I30: =+SUM(H31:H31) -> 47.88
D31: 1 | E31: 7.6 | F31: 6.3 | H31: =+ROUND(PRODUCT(D31:G31),2) -> 47.88
A33: =A$28 & ".02" -> 01.04.01.01.02 | B33: TRAZO Y REPLANTEO PRILIMINAR | C33: m2 | I33: =+SUM(H34:H34) -> 47.88
D34: 1 | E34: =+E31 -> 7.6 | F34: =+F31 -> 6.3 | H34: =+ROUND(PRODUCT(D34:G34),2) -> 47.88
A36: =A$28 & ".03" -> 01.04.01.01.03 | B36: TRAZO Y REPLANTEO DURANTE EL PROCESO | C36: m2 | I36: =SUM(H37:H39) -> 22.89
B37: Cámara húmeda | D37: 1 | E37: 2.8 | F37: 2.8 | H37: =+ROUND(PRODUCT(D37:G37),2) -> 7.84
B38: Cámara de válvulas | D38: 1 | E38: 1.6 | F38: 1.4 | H38: =+ROUND(PRODUCT(D38:G38),2) -> 2.24
B39: Vereda | D39: 1 | E39: área | F39: 12.81 | H39: =+ROUND(PRODUCT(D39:G39),2) -> 12.81
A41: =A$27 & ".02" -> 01.04.01.02 | B41: MOVIMIENTO DE TIERRAS
A43: =A41& ".01" -> 01.04.01.02.01 | B43: EXCAVACION MANUAL EN TERRENO NORMAL | C43: m3 | I43: =+SUM(H44:H44) -> 13.37
B44: Ver plano de movimiento de tierras - CTL-PMT-01 | D44: 1 | G44: Volumen | H44: 13.37
A46: =A41& ".02" -> 01.04.01.02.02 | B46: NIVELACIÓN INTERIOR Y APISONADO (MANUAL) | C46: m2 | I46: =+SUM(H47:H49) -> 22.89
B47: Cámara húmeda | D47: 1 | E47: 2.8 | F47: 2.8 | H47: =+ROUND(PRODUCT(D47:G47),2) -> 7.84
B48: Cámara de válvulas | D48: 1 | E48: 1.6 | F48: 1.4 | H48: =+ROUND(PRODUCT(D48:G48),2) -> 2.24
B49: Vereda | D49: 1 | E49: área | F49: 12.81 | H49: =+ROUND(PRODUCT(D49:G49),2) -> 12.81
A51: =A41& ".03" -> 01.04.01.02.03 | B51: RELLENO COMPACTADO CON MATERIAL PROPIO SELECCIONADO | C51: m3 | I51: =+SUM(H52) -> 2.57
B52: Ver plano de movimiento de tierras - CTL-PMT-02 | D52: 1 | G52: Volumen | H52: 2.57
A54: =A41& ".04" -> 01.04.01.02.04 | B54: ACARREO Y ELIMINACION DE MATERIAL EXCEDENTE Dmax=30 m | C54: m3 | I54: =+SUM(H55:H56) -> 13.08
B55: Excavacion - Esponjamiento 20% | D55: 1 | F55: 1.2 | G55: =+I43 -> 13.37 | H55: =+ROUND(PRODUCT(D55:G55),2) -> 16.04
B56: Relleno - Compactacion 85% | D56: -1 | F56: 1.15 | G56: =+I51 -> 2.57 | H56: =+ROUND(PRODUCT(D56:G56),2) -> -2.96
A58: =A$26 & ".02" -> 01.04.02 | B58: CÁMARA HUMEDA O ALMACENAMIENTO DE RESERVORIO
A59: =A$58& ".01" -> 01.04.02.01 | B59: OBRAS DE CONCRETO SIMPLE
A60: =A$59& ".01" -> 01.04.02.01.01 | B60: SOLADO f'c=100 Kg/cm2, e=10 cm | C60: m2 | I60: =+SUM(H61:H61) -> 7.84
B61: Base de cámara húmeda | D61: 1 | E61: 2.8 | F61: 2.8 | H61: =+PRODUCT(D61:G61) -> 7.84
A63: =A$58& ".02" -> 01.04.02.02 | B63: OBRAS DE CONCRETO ARMADO
A64: =A$63& ".01" -> 01.04.02.02.01 | B64: CONCRETO F'C=210 KG/CM2 PARA CIMENTACIÓN Y LOSA DE FONDO | C64: m3 | I64: =+SUM(H65:H79) -> 2.24
B65: Zapata seccion 1 | D65: 1 | E65: 11.2 | F65: 0.5 | G65: 0.25 | H65: =+PRODUCT(D65:G65) -> 1.4
B70: Zapata seccion 2
D71: 1 | E71: 11.2 | F71: 0.1 | G71: 0.15 | H71: =+PRODUCT(D71:G71) -> 0.168
B75: Losa de Fondo | D75: 1 | E75: 2.8 | F75: 1.6 | G75: 0.15 | H75: =+PRODUCT(D75:G75) -> 0.672
A81: =A$63& ".02" -> 01.04.02.02.02 | B81: CONCRETO f'c=210 kg/cm2 EN MUROS | C81: m3 | I81: =SUM(H82:H83) -> 1.9035
B82: Muros laterales | D82: 2 | E82: 2.5 | F82: 0.15 | G82: 1.35 | H82: =+PRODUCT(D82:G82) -> 1.0125
B83: Muros frontal y posterior | D83: 2 | E83: 2.2 | F83: 0.15 | G83: 1.35 | H83: =+PRODUCT(D83:G83) -> 0.891
...

Sheet 1.4 METR.ACERO 5M3
B2: METRADO DE ACERO DE REFUERZO
B3: PROYECTO | D3: "CREACION DEL SERVICIO DE AGUA POTABLE RURAL Y CREACION DEL SERVICIO DE ALCANTARILLADO U OTRAS FORMAS DE DISPOSICION SANITARIA DE EXCRETAS EN EL SECTOR NUEVA ESPERANZA DE LA CC.NN. BAJO PITOCUNA DISTRITO DE RIO NEGRO, PROVINCIA DE SATIPO, DEPARTAMENTO DE JUNIN" | P3: ESTRUCTURA :
P4: RESERVORIO APOYADO V=5M3
P5: CÁMARA HÚMEDA
B6: ITEM | C6: DESCRIPCION | D6: FORMA | J6: Ø (Pulg) | K6: LONG. (m) | L6: # BARRAS | M6: # ELEMEN. | N6: LARGO TOTAL | S6: OBSERV.
L7: ELEMENTO | M7: ELEMENTO | N7: 0.25 | O7: 0.375 | P7: 0.5 | Q7: 0.625 | R7: 0.75
C8: Acero losa de fondo - eye x-x
B10: 1 | E10: 0.1 | F10: 2.71 | I10: 0.1 | J10: 0.375 | K10: =SUM(D8:I12) -> 2.91 | L10: 16 | M10: 1 | N10: =IF(J10=1/4,L10*K10*M10,"-") -> - | O10: =IF(J10=3/8,K10*L10*M10,"-") -> 46.56 | P10: =IF(J10=1/2,L10*K10*M10,"-") -> - | Q10: =IF(J10=5/8,L10*K10*M10,"-") -> - | R10: =IF(J10=3/4,K10*L10,"-") -> -
C13: Acero losa de fondo - eye x-x
B14: 2 | F14: 0.3 | G14: 0.3 | J14: 0.375 | K14: =SUM(D13:I18) -> 2.2 | L14: 16 | M14: 1 | N14: =IF(J14=1/4,L14*K14*M14,"-") -> - | O14: =IF(J14=3/8,K14*L14*M14,"-") -> 35.2 | P14: =IF(J14=1/2,L14*K14*M14,"-") -> - | Q14: =IF(J14=5/8,L14*K14*M14,"-") -> - | R14: =IF(J14=3/4,K14*L14,"-") -> -
E15: 0.24 | H15: 0.24 | I15: 0.1
D16: 0.1
E17: 0.46 | H17: 0.46
C19: Acero losa de fondo - eye y-y
E21: 0.1 | F21: 2.71 | I21: 0.1
B22: 3 | J22: 0.375 | K22: =SUM(D19:I23) -> 2.91 | L22: 16 | M22: 1 | N22: =IF(J22=1/4,L22*K22*M22,"-") -> - | O22: =IF(J22=3/8,K22*L22*M22,"-") -> 46.56 | P22: =IF(J22=1/2,L22*K22*M22,"-") -> - | Q22: =IF(J22=5/8,L22*K22*M22,"-") -> - | R22: =IF(J22=3/4,K22*L22,"-") -> -
C24: Acero losa de fondo - eye y-y
F25: 0.3 | G25: 0.3
E26: 0.24 | H26: 0.24 | I26: 0.1
B27: 4 | D27: 0.1 | J27: 0.375 | K27: =SUM(D24:I29) -> 2.2 | L27: 16 | M27: 1 | N27: =IF(J27=1/4,L27*K27*M27,"-") -> - | O27: =IF(J27=3/8,K27*L27*M27,"-") -> 35.2 | P27: =IF(J27=1/2,L27*K27*M27,"-") -> - | Q27: =IF(J27=5/8,L27*K27*M27,"-") -> - | R27: =IF(J27=3/4,K27*L27,"-") -> -
E28: 0.46 | H28: 0.46
C30: Acero horizontal muro
F31: 2.47
D32: 0.15 | I32: 0.15
B33: 5 | E33: 0.15 | F33: 2.33 | H33: 0.15 | J33: 0.375 | K33: =SUM(D30:I34) -> 5.4 | L33: 8 | M33: 4 | N33: =IF(J33=1/4,L33*K33*M33,"-") -> - | O33: =IF(J33=3/8,K33*L33*M33,"-") -> 172.8 | P33: =IF(J33=1/2,L33*K33*M33,"-") -> - | Q33: =IF(J33=5/8,L33*K33*M33,"-") -> - | R33: =IF(J33=3/4,K33*L33,"-") -> -
C35: Acero vertical muro | E35: 0.12 | F35: 0.15
E38: 1.62 | F38: 1.62
B39: 6 | J39: 0.375 | K39: =SUM(D35:I42) -> 3.81 | L39: 12 | M39: 4 | N39: =IF(J39=1/4,L39*K39*M39,"-") -> - | O39: =IF(J39=3/8,K39*L39*M39,"-") -> 182.88 | P39: =IF(J39=1/2,L39*K39*M39,"-") -> - | Q39: =IF(J39=5/8,L39*K39*M39,"-") -> - | R39: =IF(J39=3/4,K39*L39,"-") -> -
E42: 0.15 | F42: 0.15
C43: Acero en losa superior en eje x-x
F44: 2.64
B45: 7 | J45: 0.375 | K45: =SUM(D43:I46) -> 2.64 | L45: 13 | M45: 1 | N45: =IF(J45=1/4,L45*K45*M45,"-") -> - | O45: =IF(J45=3/8,K45*L45*M45,"-") -> 34.32 | P45: =IF(J45=1/2,L45*K45*M45,"-") -> - | Q45: =IF(J45=5/8,L45*K45*M45,"-") -> - | R45: =IF(J45=3/4,K45*L45,"-") -> -
C47: Acero en losa superior en eje y-y
F48: 2.64
B49: 8 | J49: 0.375 | K49: =SUM(D47:I51) -> 2.64 | L49: 13 | M49: 1 | N49: =IF(J49=1/4,L49*K49*M49,"-") -> - | O49: =IF(J49=3/8,K49*L49*M49,"-") -> 34.32 | P49: =IF(J49=1/2,L49*K49*M49,"-") -> - | Q49: =IF(J49=5/8,L49*K49*M49,"-") -> - | R49: =IF(J49=3/4,K49*L49,"-") -> -
C52: Acero en horizontal en borde de soporte de tapa
F53: 0.74
B54: 9 | E54: 0.15 | F54: 0.15 | J54: 0.375 | K54: =SUM(D52:I56) -> 1.04 | L54: 4 | M54: 1 | N54: =IF(J54=1/4,L54*K54*M54,"-") -> - | O54: =IF(J54=3/8,K54*L54*M54,"-") -> 4.16 | P54: =IF(J54=1/2,L54*K54*M54,"-") -> - | Q54: =IF(J54=5/8,L54*K54*M54,"-") -> - | R54: =IF(J54=3/4,K54*L54,"-") -> -
J57: LONGITUD TOTAL (M) | N57: =SUM(N8:N29) -> 0 | O57: =SUM(O8:O56) -> 592 | P57: =SUM(P8:P29) -> 0 | Q57: =SUM(Q8:Q29) -> 0 | R57: =SUM(R8:R29) -> 0
J58: PESO x M.L (kg) | N58: 0.22 | O58: 0.56 | P58: 0.994 | Q58: 1.552 | R58: 2.235
...

Sheet 1.5 L-ADUCC.
A2: HOJA DE METRADOS DE AGUA POTABLE
A3: "CREACION DEL SERVICIO DE AGUA POTABLE RURAL Y CREACION DEL SERVICIO DE ALCANTARILLADO U OTRAS FORMAS DE DISPOSICION SANITARIA DE EXCRETAS EN EL SECTOR NUEVA ESPERANZA DE LA CC.NN. BAJO PITOCUNA DISTRITO DE RIO NEGRO, PROVINCIA DE SATIPO, DEPARTAMENTO DE JUNIN"
A4: LINEA DE ADUCCION
B6: Zanja Tipica | C6: =+C8&" x "&C7&" m" -> 0.5 x 0.7 m | D6: normal | E6: MANGUERA HDPE - 1 1/2"
B7: Altura | C7: 0.7 | D7: m
B8: Ancho | C8: 0.5 | D8: m
B9: Cama de Apoyo | C9: 0.1 | D9: m
B10: Capas de relleno con material propio | C10: =C7-C9 -> 0.6 | D10: m
A12: PARTIDA | B12: DESCRIPCION | C12: UNIDAD | D12: VECES | E12: LONGITUD | F12: ANCHO | G12: ALTURA | H12: SUB-TOTAL | I12: TOTAL
A13: =+"01.05" -> 01.05 | B13: =A4&" L= "&E17&"m" -> LINEA DE ADUCCION L= 185.94m | E13: =SUM(E14:E14) -> 185.94
B14: MANGUERA HDPE Ø 1 1/2" PN-10 TERRENO SUELTOS | C14: ML | D14: 1 | E14: 185.94
A16: =A$13 & ".01" -> 01.05.01 | B16: TRABAJOS PRELIMINARES
A17: =A$16 & ".01" -> 01.05.01.01 | B17: LIMPIEZA Y DESBROCE DE TERRENO MANUAL | C17: ML | D17: 1 | E17: =E13 -> 185.94 | H17: =+ROUND(PRODUCT(D17:G17),2) -> 185.94 | I17: =+H17 -> 185.94
A18: =A$16 & ".02" -> 01.05.01.02 | B18: TRAZO Y REPLANTEO PRELIMINAR EN LINEAS Y REDES | C18: ML | D18: 1 | E18: =E13 -> 185.94 | H18: =+ROUND(PRODUCT(D18:G18),2) -> 185.94 | I18: =+H18 -> 185.94
A19: =A$16 & ".03" -> 01.05.01.03 | B19: TRAZO Y REPLANTEO DURANTE EL PROCESO EN LINEAS Y REDES | C19: ML | D19: 1 | E19: =E13 -> 185.94 | H19: =+ROUND(PRODUCT(D19:G19),2) -> 185.94 | I19: =+H19 -> 185.94
A21: =A$13 & ".02" -> 01.05.02 | B21: MOVIMIENTO DE TIERRAS
A22: =$A$21 & ".01" -> 01.05.02.01 | B22: EXCAVACION MANUAL EN TERRENO SUELTO DE ZANJA DE 0.40 x 0.30 m P/MANGUERA HDPE | C22: ML | D22: 1 | E22: =E14 -> 185.94 | H22: =+ROUND(PRODUCT(D22:G22),2) -> 185.94 | I22: =+H22 -> 185.94
A23: =$A$21 & ".02" -> 01.05.02.02 | B23: RELLENO DE ZANJA, CON MAT. PROPIO, E=0.40m A=0.30m P/MANGUERA HDPE | C23: ML | D23: 1 | E23: =E13 -> 185.94 | H23: =+ROUND(PRODUCT(D23:G23),2) -> 185.94 | I23: =+H23 -> 185.94
A24: =$A$21 & ".03" -> 01.05.02.03 | B24: ACARREO Y ELIMINACION DE MAT. EXCEDENTE Dmax=30 m | C24: ML | D24: 1 | E24: 4.4 | H24: =+ROUND(PRODUCT(D24:G24),2) -> 4.4 | I24: =+H24 -> 4.4
A25: =A$13 & ".03" -> 01.05.03 | B25: SUMINISTRO E INSTALACION DE TUBERIAS
A26: =A25 & ".01" -> 01.05.03.01 | B26: SUMINISTRO E INSTALACION DE MANGUERA HDPE NTP - ISO 4427: 2008 PE 80, PN=10, ø=44.4mm | C26: ML | D26: 1 | E26: =SUM(E14:E14) -> 185.94 | H26: =+ROUND(PRODUCT(D26:G26),2) -> 185.94 | I26: =+H26 -> 185.94
A28: =A$13 & ".04" -> 01.05.04 | B28: SUMINISTRO E INSTALACION DE ACCESORIOS
A29: =A28 & ".01" -> 01.05.04.01 | B29: SUMINISTRO E INSTALACION DE UNION ENLACE P/MANG. HDPE, PN-10 ø=44.4mm | C29: UND | D29: 1 | H29: =+ROUND(PRODUCT(D29:G29),2) -> 1 | I29: =+H29 -> 1
A30: =A29 & ".02" -> 01.05.04.01.02 | B30: SUMINISTRO E INSTALACION DE UNION HDPE, PN=8" ø=43.4 MM | C30: UND | H30: =+ROUND(PRODUCT(D30:G30),2) -> 0 | I30: =+H30 -> 0
A32: =A$13 & ".05" -> 01.05.05 | B32: PRUEBA HIDRAULICA
A33: =A32 &".01" -> 01.05.05.01 | B33: PRUEBA HIDRAULICA Y DESINFECCION DE LA TUBERIA | C33: ML | D33: 1 | E33: =SUM(E14:E14) -> 185.94 | H33: =+ROUND(PRODUCT(D33:G33),2) -> 185.94 | I33: =+H33 -> 185.94

Sheet 1.6 RED DE DISTRIB.
B2: HOJA DE METRADOS DE AGUA POTABLE
B3: "CREACION DEL SERVICIO DE AGUA POTABLE RURAL Y CREACION DEL SERVICIO DE ALCANTARILLADO U OTRAS FORMAS DE DISPOSICION SANITARIA DE EXCRETAS EN EL SECTOR NUEVA ESPERANZA DE LA CC.NN. BAJO PITOCUNA DISTRITO DE RIO NEGRO, PROVINCIA DE SATIPO, DEPARTAMENTO DE JUNIN"
B4: RED DE DISTRIBUCION
C6: Zanja Tipica | D6: =+D8&" x "&D7&" m" -> 0.5 x 0.8 m | E6: Normal | F6: TUBERIA PVC - 3/4",1"
C7: Altura | D7: 0.8 | E7: m
C8: Ancho | D8: 0.5 | E8: m
C9: Cama de Apoyo | D9: 0.1 | E9: m
C10: 1ra Capas de compactacion | D10: 0.3 | E10: m
C11: 2ra Capas de compactacion | D11: 0.4 | E11: m
C13: Zanja Tipica | D13: =+D15&" x "&D14&" m" -> 0.5 x 1 m | E13: Normal | F13: TUBERIA PVC CARRETERA - 3/4",1"
C14: Altura | D14: 1 | E14: m
C15: Ancho | D15: 0.5 | E15: m
C16: Cama de Apoyo | D16: 0.1 | E16: m
C17: 1ra Capas de compactacion | D17: 0.3 | E17: m
C18: 2ra Capas de compactacion | D18: 0.6 | E18: m
B21: PARTIDA | C21: DESCRIPCION | D21: UNIDAD | E21: VECES | F21: LONGITUD | G21: ANCHO | H21: ALTURA | I21: SUB-TOTAL | J21: TOTAL
B22: =+"01.06" -> 01.06 | C22: =B4&" L= "&F54&"m" -> RED DE DISTRIBUCION L= 1066.66m | F22: =SUM(F23:F51) -> 1097.16
C23: Tubería PVC Ø 3/4" C-10 - TERRENO NORMAL EN CARRETERA | D23: ML | E23: 1 | F23: =SUM(E24:E27) -> 86.04
C24: T-10 | E24: 31.83
C25: T-12 | E25: 27.29
C26: T-13 | E26: 53.92
C27: MENOS T-13 PRUFUNDIZADA TUB 13 | E27: -27
C29: Tubería PVC Ø 1" C-10 - TERRENO NORMAL EN CARRETERA | D29: ML | E29: 1 | F29: =SUM(E30:E37) -> 258.29
C30: T-11-INICIO | E30: 7.75
C31: T-11-FINAL | E31: 4.7
C32: T-14 | E32: 44.4
C33: T-18 | E33: 64.18
C34: T-19 | E34: 43.6
C35: T-20 | E35: 23.21
C36: T-21 | E36: 29.37
C37: T-23 | E37: 41.08
C39: Tubería PVC Ø 3/4" C-10 - TERRENO NORMAL | D39: ML | E39: 1 | F39: =SUM(E40:E42) -> 305.94
C40: TOTAL | E40: 414.98
C41: TUBERIA EN CARRETERA | E41: =-F23 -> -86.04
C42: TUBERIA PROFUNDIZADA TUBERIA 15 | E42: -23
C44: Tubería PVC Ø 1" C-10 - TERRENO NORMAL | D44: ML | E44: 1 | F44: =SUM(E45:E49) -> 396.89
C45: TOTAL | E45: 682.18
C46: MENOS TUBERIA EN CARRETERA | E46: =-F29 -> -258.29
C47: MENOS TUBERIA DE CRUCE EN PUENTE MODULAR | E47: -24.5
C48: MENOS TUBERIA CRUCE EN ALCANTARILLA TMC 24" | E48: -6
...

Sheet 1.7 VALV-AIRE
B1: HOJA DE METRADOS DE AGUA POTABLE
B2: "CREACION DEL SERVICIO DE AGUA POTABLE RURAL Y CREACION DEL SERVICIO DE ALCANTARILLADO U OTRAS FORMAS DE DISPOSICION SANITARIA DE EXCRETAS EN EL SECTOR NUEVA ESPERANZA DE LA CC.NN. BAJO PITOCUNA DISTRITO DE RIO NEGRO, PROVINCIA DE SATIPO, DEPARTAMENTO DE JUNIN"
B3: VALVULA DE AIRE
L10: N° | M10: ACCESORIOS | N10: UNIDAD
L11: 1 | M11: Valvula de aire | N11: 1
L12: 2 | M12: Niple PVC L=1" | N12: 4
L13: 3 | M13: Union universal PVC | N13: 2
L14: 4 | M14: Valvula compuerta Bronce | N14: 1 | O14: Ø = 3/4"
L15: 5 | M15: Reduccion PVC SP | N15: 1
L16: 6 | M16: Tee PVC SP | N16: 1
B18: PARTIDA | C18: DESCRIPCION | D18: UNIDAD | E18: VECES | F18: LONGITUD | G18: ANCHO | H18: ALTURA | I18: SUB-TOTAL | J18: TOTAL | L18: =+B3&O14& " x" -> VALVULA DE AIRE Ø = 3/4" x
B19: =+"01.07" -> 01.07 | C19: =+B3&" ("&E19&" und.)" -> VALVULA DE AIRE (1 und.) | E19: =E20+E21 -> 1
C20: =+$L$18&L20 -> VALVULA DE AIRE Ø = 3/4" x Ø = 3/4" | E20: 1 | L20: Ø = 3/4"
B22: =B$19 & ".01" -> 01.07.01 | C22: TRABAJOS PRELIMINARES | E22: =+$E$19 -> 1 | L22: Descripcion | M22: Medida | N22: Unidad
B23: =B$22 & ".01" -> 01.07.01.01 | C23: LIMPIEZA Y DESBROCE DE TERRENO MANUAL | D23: m2 | I23: =SUM(I24) -> 2.72 | J23: =+I23*$E$22 -> 2.72 | L23: Caja de Valvulas
C24: Caja de valvula | E24: 1 | F24: =+M51 -> 1.65 | G24: =+M50 -> 1.65 | I24: =+ROUND(PRODUCT(E24:G24),2) -> 2.72 | L24: Ancho | M24: 0.6 | N24: m
L25: Largo | M25: 0.6 | N25: m
B26: =B$22 & ".02" -> 01.07.01.02 | C26: TRAZO Y REPLANTEO PRELIMINAR PARA ESTRUCTURAS | D26: m2 | I26: =SUM(I27) -> 2.72 | J26: =+I26*$E$22 -> 2.72 | L26: Altura | M26: 0.75 | N26: m
C27: Caja de valvula | E27: 1 | F27: =+F24 -> 1.65 | G27: =+G24 -> 1.65 | I27: =+ROUND(PRODUCT(E27:G27),2) -> 2.72 | L27: Uña | M27: 0.1 | N27: m
L28: Espesor de muro | M28: 0.1 | N28: m
B29: =B$22 & ".03" -> 01.07.01.03 | C29: TRAZO Y REPLANTEO DURANTE EL PROCESO PARA ESTRUCTURAS | D29: m2 | I29: =SUM(I30) -> 2.72 | J29: =+I29*$E$22 -> 2.72
C30: Caja de valvula | E30: 1 | F30: =+F27 -> 1.65 | G30: =+G27 -> 1.65 | I30: =+ROUND(PRODUCT(E30:G30),2) -> 2.72
B32: =B$19 & ".02" -> 01.07.02 | C32: MOVIMIENTO DE TIERRAS | E32: =+$E$19 -> 1 | L32: Cimentacion
B33: =B$32 & ".01" -> 01.07.02.01 | C33: EXCAVACION MANUAL EN TERRENO NORMAL | D33: m3 | I33: =SUM(I34:I42) -> 1.9 | J33: =+I33*$E$32 -> 1.9 | L33: Ancho | M33: =+M24+2*M28+2*M27 -> 1 | N33: m
C34: Caja de valvula | E34: 1 | F34: Volumen | H34: =+G39/6*((2*G35+G37)*G36+(2*G37+G35)*G38) -> 1.84275 | I34: =+ROUND(PRODUCT(E34:H34),2) -> 1.84 | L34: Largo | M34: =+M25+2*M28+2*M27 -> 1 | N34: m
F35: a | G35: =+M50 -> 1.65 | L35: Espesor de losa | M35: 0.1 | N35: m
F36: b | G36: =+M51 -> 1.65 | L36: Solado | M36: 0.05 | N36: m
C37: Se considera 0.10m de | F37: a´ | G37: =+M46 -> 1.2 | L37: Uñas de cimentacion
C38: excavacion y talud 1:0.25 | F38: b´ | G38: =+M47 -> 1.2 | L38: Espesor | M38: 0.1 | N38: m
F39: h | G39: =+M53 -> 0.9 | L39: Profundidad | M39: 0.2 | N39: m
L40: Ancho | M40: 0.2 | N40: m
C41: Uña de cimentación | E41: 1 | F41: =+M42+M38 -> 0.235 | G41: =+M40+M38 -> 0.3 | H41: =+M39 -> 0.2 | I41: =+ROUND(PRODUCT(E41:H41),2) -> 0.01
C42: Solado | E42: 1 | F42: =+M34 -> 1 | G42: =+M33 -> 1 | H42: =+M36 -> 0.05 | I42: =+ROUND(PRODUCT(E42:H42),2) -> 0.05 | L42: Largo | M42: 0.135 | N42: m
L43: Excavacion
B44: =B$32 & ".02" -> 01.07.02.02 | C44: RELLENO CON MATERIAL PROPIO SELECCIONADO | D44: m3 | I44: =SUM(I45:I47) -> 1.26 | J44: =+I44*$E$32 -> 1.26 | L44: Fondo
C45: Volumen de excavacion | E45: 1 | H45: =+H34 -> 1.84275 | I45: =+ROUND(PRODUCT(E45:H45),2) -> 1.84 | L45: Excavacion | M45: 0.1 | N45: m
C46: Volumen de muros | E46: -1 | F46: =+M25+M28*2 -> 0.8 | G46: =+M24+2*M28 -> 0.8 | H46: =+M26 -> 0.75 | I46: =+ROUND(PRODUCT(E46:H46),2) -> -0.48 | L46: Ancho (a´) | M46: =+M33+2*M45 -> 1.2 | N46: m
C47: Volumen de losa | E47: -1 | F47: =+M34 -> 1 | G47: =+M33 -> 1 | H47: =+M35 -> 0.1 | I47: =+ROUND(PRODUCT(E47:H47),2) -> -0.1 | L47: Largo (b´) | M47: =+M34+2*M45 -> 1.2 | N47: m
L48: Superior
B49: =B$32 & ".03" -> 01.07.02.03 | C49: ACARREO Y ELIMINACION DE MAT. EXCEDENTE Dmax=30 m | D49: m3 | I49: =SUM(I50:I51) -> 0.88 | J49: =+I49*$E$32 -> 0.88 | L49: Excavacion | M49: =+M52*M53 -> 0.225 | N49: m
...

Sheet 1.8. VALV-PURGA T-1
B1: METRADOS DEL SISTEMA DE AGUA POTABLE
B2: "CREACION DEL SERVICIO DE AGUA POTABLE RURAL Y CREACION DEL SERVICIO DE ALCANTARILLADO U OTRAS FORMAS DE DISPOSICION SANITARIA DE EXCRETAS EN EL SECTOR NUEVA ESPERANZA DE LA CC.NN. BAJO PITOCUNA DISTRITO DE RIO NEGRO, PROVINCIA DE SATIPO, DEPARTAMENTO DE JUNIN"
B3: VALVULA DE PURGA TIPO 1
L4: N° | M4: ACCESORIOS | N4: UNIDAD
L5: 1 | M5: Valvula compuerta Bronce | N5: 1
L6: 2 | M6: Niple PVC L=2" | N6: 2
L7: 3 | M7: Union universal PVC | N7: 2
L8: 4 | M8: Adaptador UPR PVC | N8: 2
L9: 5 | M9: Niple PVC L=8" | N9: 3
L10: 6 | M10: Codo PVC SP x 45° | N10: 4
L11: 7 | M11: Niple PVC L=22" | N11: 1
L12: 8 | M12: Niple PVC L=7" | N12: 1
L13: 9 | M13: Tee PVC SP | N13: 1
L14: 10 | M14: Tapón macho F°G° | N14: 1
M15: Tuberia PVC C-10 | N15: 3
B18: PARTIDA | C18: DESCRIPCION | D18: UNIDAD | E18: VECES | F18: LONGITUD | G18: ANCHO | H18: ALTURA | I18: SUB-TOTAL | J18: TOTAL | L18: VALVULA DE PURGA TIPO 1 (8 und.)
B19: =+"01.08" -> 01.08 | C19: VALVULA DE PUGA (5 und) | E19: =+SUM(E20:E20) -> 2
C20: =+$B$3&L20 -> VALVULA DE PURGA TIPO 1 Ø = 1 1/2" | E20: 2 | L20: Ø = 1 1/2"
B21: =B$19 & ".01" -> 01.08.01 | C21: VALVULAS DE PURGA TIPO 1 (2 und)
B22: =B$19 & ".01.01" -> 01.08.01.01 | C22: TRABAJOS PRELIMINARES | E22: =+$E$19 -> 2 | L22: Descripcion | M22: Medida | N22: Unidad
B23: =B$22 & ".01" -> 01.08.01.01.01 | C23: LIMPIEZA Y DESBROCE DE TERRENO MANUAL | D23: m2 | I23: =SUM(I24:I25) -> 5.56 | J23: =+I23*$E$22 -> 11.12 | L23: Caja de Valvulas
C24: Caja de valvula | E24: 1 | F24: =+M45 -> 1.6 | G24: =+M44 -> 1.6 | I24: =+ROUND(PRODUCT(E24:G24),2) -> 2.56 | L24: Ancho | M24: 0.6 | N24: m
C25: Tuberia de limpieza | E25: 1 | F25: 3 | G25: 1 | I25: =+ROUND(PRODUCT(E25:H25),2) -> 3 | L25: Largo | M25: 0.6 | N25: m
L26: Altura | M26: 0.7 | N26: m
B27: =B$22 & ".02" -> 01.08.01.01.02 | C27: TRAZO Y REPLANTEO PRELIMINAR PARA ESTRUCTURAS | D27: m2 | I27: =SUM(I28:I29) -> 5.56 | J27: =+I27*$E$22 -> 11.12 | L27: Uña | M27: 0.1 | N27: m
C28: Caja de valvula | E28: 1 | F28: =+F24 -> 1.6 | G28: =+G24 -> 1.6 | I28: =+ROUND(PRODUCT(E28:G28),2) -> 2.56 | L28: Espesor de muro | M28: 0.1 | N28: m
C29: Tuberia de limpieza | E29: 1 | F29: =+F25 -> 3 | G29: =+G25 -> 1 | I29: =+ROUND(PRODUCT(E29:H29),2) -> 3 | L29: Cimentacion B
B31: =B$22 & ".03" -> 01.08.01.01.03 | C31: TRAZO Y REPLANTEO DURANTE EL PROCESO PARA ESTRUCTURAS | D31: m2 | I31: =SUM(I32:I33) -> 5.56 | J31: =+I31*$E$22 -> 11.12
C32: Caja de valvula | E32: 1 | F32: =+F28 -> 1.6 | G32: =+G28 -> 1.6 | I32: =+ROUND(PRODUCT(E32:G32),2) -> 2.56
C33: Tuberia de limpieza | E33: 1 | F33: =+F29 -> 3 | G33: =+G29 -> 1 | I33: =+ROUND(PRODUCT(E33:H33),2) -> 3
L34: Ancho | M34: =+M24+2*M28+2*M27 -> 1 | N34: m
B35: =B$19 & ".01.02" -> 01.08.01.02 | C35: MOVIMIENTO DE TIERRAS | E35: =+$E$19 -> 2 | L35: Largo | M35: =+M25+2*M28+2*M27 -> 1 | N35: m
B36: =B$35 & ".01" -> 01.08.01.02.01 | C36: EXCAVACION MANUAL EN TERRENO NORMAL | D36: m3 | I36: =SUM(I37:I44) -> 3.38 | J36: =+I36*$E$35 -> 6.76 | L36: Espesor de losa | M36: 0.1 | N36: m
C37: Caja de valvula | E37: 1 | F37: Volumen | H37: =+G42/6*((2*G38+G40)*G39+(2*G40+G38)*G41) -> 1.5786667 | I37: =+ROUND(PRODUCT(E37:H37),2) -> 1.58 | L37: Excavacion
F38: a | G38: =+M44 -> 1.6 | L38: Fondo
F39: b | G39: =+M45 -> 1.6 | L39: Excavacion | M39: 0.1 | N39: m
C40: Se considera 0.10m de | F40: a´ | G40: =+M40 -> 1.2 | L40: Ancho (a´) | M40: =+M34+2*M39 -> 1.2 | N40: m
C41: excavacion y talud 1:0.25 | F41: b´ | G41: =+M41 -> 1.2 | L41: Largo (b´) | M41: =+M35+2*M39 -> 1.2 | N41: m
F42: h | G42: =+M47 -> 0.8 | L42: Superior
L43: Excavacion | M43: =+M46*M47 -> 0.2 | N43: m
...

Sheet 1.8.1 M.ACERO T-01
A2: METRADOS Del SISTEMA DE AGUA POTABLE
A3: "CREACION DEL SERVICIO DE AGUA POTABLE RURAL Y CREACION DEL SERVICIO DE ALCANTARILLADO U OTRAS FORMAS DE DISPOSICION SANITARIA DE EXCRETAS EN EL SECTOR NUEVA ESPERANZA DE LA CC.NN. BAJO PITOCUNA DISTRITO DE RIO NEGRO, PROVINCIA DE SATIPO, DEPARTAMENTO DE JUNIN"
A4: METRADO DE CAMARA ROMPE PRESION T 06
A6: =+'[26]Captación Dique'!B140 -> 01.03.04.03 | D6: =+'[26]Captación Dique'!C140 -> ACERO f'y=4200 kg/cm2
A8: DESCRIPCION | D8: ELEMENTO | J8: Ø (Pulg.) | K8: CANTIDAD | L8: N° DE ELEMENTOS | M8: LONG. DEL ELEMENTO (m) | N8: LONGITUD (m)
N9: 1/4" | O9: 3/8" | P9: 1/2" | Q9: 5/8" | R9: 3/4" | S9: 1"
A10: CAMARA HUMEDA | B10: Muro y Losa | C10: Acero Vertical
F12: 0.95 | J12: 3/8" | K12: 4 | L12: 4 | M12: =+F12+G14 -> 1.15 | N12: =IF(+$J12=N$9,+$K12*$L12*$M12,0) -> 0 | O12: =IF(+$J12=O$9,+$K12*$L12*$M12,0) -> 18.4 | P12: =IF(+$J12=P$9,+$K12*$L12*$M12,0) -> 0 | Q12: =IF(+$J12=Q$9,+$K12*$L12*$M12,0) -> 0 | R12: =IF(+$J12=R$9,+$K12*$L12*$M12,0) -> 0 | S12: =IF(+$J12=S$9,+$K12*$L12*$M12,0) -> 0
G14: 0.2
C15: Acero Horizontal | F15: 0.2
E16: 0.2 | F16: 0.7
F17: 0.7 | H17: 0.7 | J17: 3/8" | K17: 1 | L17: 4 | M17: =+F19+H17+E16+F15+F16+F17 -> 3.2 | N17: =IF(+$J17=N$9,+$K17*$L17*$M17,0) -> 0 | O17: =IF(+$J17=O$9,+$K17*$L17*$M17,0) -> 12.8 | P17: =IF(+$J17=P$9,+$K17*$L17*$M17,0) -> 0 | Q17: =IF(+$J17=Q$9,+$K17*$L17*$M17,0) -> 0 | R17: =IF(+$J17=R$9,+$K17*$L17*$M17,0) -> 0 | S17: =IF(+$J17=S$9,+$K17*$L17*$M17,0) -> 0
F19: 0.7
C20: Losa - Acero Longitudinal y Transversal
F22: 0.92 | J22: 3/8" | K22: 4 | L22: 4 | M22: =+F22 -> 0.92 | N22: =IF(+$J22=N$9,+$K22*$L22*$M22,0) -> 0 | O22: =IF(+$J22=O$9,+$K22*$L22*$M22,0) -> 14.72 | P22: =IF(+$J22=P$9,+$K22*$L22*$M22,0) -> 0 | Q22: =IF(+$J22=Q$9,+$K22*$L22*$M22,0) -> 0 | R22: =IF(+$J22=R$9,+$K22*$L22*$M22,0) -> 0 | S22: =IF(+$J22=S$9,+$K22*$L22*$M22,0) -> 0
C25: Losa - Acero Transversal
F27: 4.44 | J27: 3/8" | K27: 0 | L27: 3 | M27: =+F27+H26+E26 -> 4.44 | N27: =IF(+$J27=N$9,+$K27*$L27*$M27,0) -> 0 | O27: =IF(+$J27=O$9,+$K27*$L27*$M27,0) -> 0 | P27: =IF(+$J27=P$9,+$K27*$L27*$M27,0) -> 0 | Q27: =IF(+$J27=Q$9,+$K27*$L27*$M27,0) -> 0 | R27: =IF(+$J27=R$9,+$K27*$L27*$M27,0) -> 0 | S27: =IF(+$J27=S$9,+$K27*$L27*$M27,0) -> 0
C30: Zapata - Acero Longitudinal
F32: 2.98 | J32: 3/8" | K32: 0 | L32: 4 | M32: =+F32 -> 2.98 | N32: =IF(+$J32=N$9,+$K32*$L32*$M32,0) -> 0 | O32: =IF(+$J32=O$9,+$K32*$L32*$M32,0) -> 0 | P32: =IF(+$J32=P$9,+$K32*$L32*$M32,0) -> 0 | Q32: =IF(+$J32=Q$9,+$K32*$L32*$M32,0) -> 0 | R32: =IF(+$J32=R$9,+$K32*$L32*$M32,0) -> 0 | S32: =IF(+$J32=S$9,+$K32*$L32*$M32,0) -> 0
C35: Zapata - Acero Transversal
F37: 4.44 | J37: 3/8" | K37: 0 | L37: 3 | M37: =+F37 -> 4.44 | N37: =IF(+$J37=N$9,+$K37*$L37*$M37,0) -> 0 | O37: =IF(+$J37=O$9,+$K37*$L37*$M37,0) -> 0 | P37: =IF(+$J37=P$9,+$K37*$L37*$M37,0) -> 0 | Q37: =IF(+$J37=Q$9,+$K37*$L37*$M37,0) -> 0 | R37: =IF(+$J37=R$9,+$K37*$L37*$M37,0) -> 0 | S37: =IF(+$J37=S$9,+$K37*$L37*$M37,0) -> 0
B40: Muro segundario | C40: Acero Vertical (interior y exterior)
F42: 1.23 | J42: 1/2" | K42: 0 | L42: 4 | M42: =+F42+G44 -> 1.33 | N42: =IF(+$J42=N$9,+$K42*$L42*$M42,0) -> 0 | O42: =IF(+$J42=O$9,+$K42*$L42*$M42,0) -> 0 | P42: =IF(+$J42=P$9,+$K42*$L42*$M42,0) -> 0 | Q42: =IF(+$J42=Q$9,+$K42*$L42*$M42,0) -> 0 | R42: =IF(+$J42=R$9,+$K42*$L42*$M42,0) -> 0 | S42: =IF(+$J42=S$9,+$K42*$L42*$M42,0) -> 0
G44: 0.1
C45: Acero Horizontal
J47: 3/8" | K47: 0 | L47: 7 | M47: =+F48 -> 0.839 | N47: =IF(+$J47=N$9,+$K47*$L47*$M47,0) -> 0 | O47: =IF(+$J47=O$9,+$K47*$L47*$M47,0) -> 0 | P47: =IF(+$J47=P$9,+$K47*$L47*$M47,0) -> 0 | Q47: =IF(+$J47=Q$9,+$K47*$L47*$M47,0) -> 0 | R47: =IF(+$J47=R$9,+$K47*$L47*$M47,0) -> 0 | S47: =IF(+$J47=S$9,+$K47*$L47*$M47,0) -> 0
F48: 0.839
C50: Zapata - Acero Longitudinal
J52: 1/2" | K52: 0 | L52: 6 | M52: =+F53 -> 0.839 | N52: =IF(+$J52=N$9,+$K52*$L52*$M52,0) -> 0 | O52: =IF(+$J52=O$9,+$K52*$L52*$M52,0) -> 0 | P52: =IF(+$J52=P$9,+$K52*$L52*$M52,0) -> 0 | Q52: =IF(+$J52=Q$9,+$K52*$L52*$M52,0) -> 0 | R52: =IF(+$J52=R$9,+$K52*$L52*$M52,0) -> 0 | S52: =IF(+$J52=S$9,+$K52*$L52*$M52,0) -> 0
F53: =+F48 -> 0.839
C55: Zapata - Acero Transversal
F57: 0.91 | J57: 1/2" | K57: 0 | L57: =+L42 -> 4 | M57: =+F57 -> 0.91 | N57: =IF(+$J57=N$9,+$K57*$L57*$M57,0) -> 0 | O57: =IF(+$J57=O$9,+$K57*$L57*$M57,0) -> 0 | P57: =IF(+$J57=P$9,+$K57*$L57*$M57,0) -> 0 | Q57: =IF(+$J57=Q$9,+$K57*$L57*$M57,0) -> 0 | R57: =IF(+$J57=R$9,+$K57*$L57*$M57,0) -> 0 | S57: =IF(+$J57=S$9,+$K57*$L57*$M57,0) -> 0
G60: 0.137
F62: 1.101 | J62: 1/2" | K62: 0 | L62: 7 | M62: =+F62+F64+G60 -> 1.488 | N62: =IF(+$J62=N$9,+$K62*$L62*$M62,0) -> 0 | O62: =IF(+$J62=O$9,+$K62*$L62*$M62,0) -> 0 | P62: =IF(+$J62=P$9,+$K62*$L62*$M62,0) -> 0 | Q62: =IF(+$J62=Q$9,+$K62*$L62*$M62,0) -> 0 | R62: =IF(+$J62=R$9,+$K62*$L62*$M62,0) -> 0 | S62: =IF(+$J62=S$9,+$K62*$L62*$M62,0) -> 0
F64: 0.25
C66: Acero Horizontal
F67: 1.26 | J67: 1/2" | K67: 0 | L67: 11 | M67: =+F67 -> 1.26 | N67: =IF(+$J67=N$9,+$K67*$L67*$M67,0) -> 0 | O67: =IF(+$J67=O$9,+$K67*$L67*$M67,0) -> 0 | P67: =IF(+$J67=P$9,+$K67*$L67*$M67,0) -> 0 | Q67: =IF(+$J67=Q$9,+$K67*$L67*$M67,0) -> 0 | R67: =IF(+$J67=R$9,+$K67*$L67*$M67,0) -> 0 | S67: =IF(+$J67=S$9,+$K67*$L67*$M67,0) -> 0
C70: Acero Vertical (Frontal) | G70: 0.2
F72: =+F67 -> 1.26 | J72: 1/2" | K72: 0 | L72: 7 | M72: =+F72+G70+G74 -> 1.96 | N72: =IF(+$J72=N$9,+$K72*$L72*$M72,0) -> 0 | O72: =IF(+$J72=O$9,+$K72*$L72*$M72,0) -> 0 | P72: =IF(+$J72=P$9,+$K72*$L72*$M72,0) -> 0 | Q72: =IF(+$J72=Q$9,+$K72*$L72*$M72,0) -> 0 | R72: =IF(+$J72=R$9,+$K72*$L72*$M72,0) -> 0 | S72: =IF(+$J72=S$9,+$K72*$L72*$M72,0) -> 0
G74: 0.5
...

Sheet 1.8.2 VALV-PURGA T-2
B1: PLANILLA DE METRADOS Del SISTEMA DE AGUA POTABLE
B2: "CREACION DEL SERVICIO DE AGUA POTABLE RURAL Y CREACION DEL SERVICIO DE ALCANTARILLADO U OTRAS FORMAS DE DISPOSICION SANITARIA DE EXCRETAS EN EL SECTOR NUEVA ESPERANZA DE LA CC.NN. BAJO PITOCUNA DISTRITO DE RIO NEGRO, PROVINCIA DE SATIPO, DEPARTAMENTO DE JUNIN"
B3: VALVULA DE PURGA TIPO 2
L4: N° | M4: ACCESORIOS | N4: UNIDAD
L5: 1 | M5: Valvula compuerta Bronce | N5: 1
L6: 2 | M6: Niple PVC L=2" | N6: 2
L7: 3 | M7: Union universal PVC | N7: 2
L8: 4 | M8: Adaptador UPR PVC | N8: 2
L9: 5 | M9: Niple PVC L=8" | N9: 3
L10: 6 | M10: Codo PVC SP x 45° | N10: 4
L11: 7 | M11: Niple PVC L=22" | N11: 1
L12: 8 | M12: Niple PVC L=7" | N12: 1
L13: 9 | M13: Tee PVC SP | N13: 1
L14: 10 | M14: Tapón macho F°G° | N14: 1
M15: Tuberia PVC C-10 | N15: 3
B18: PARTIDA | C18: DESCRIPCION | D18: UNIDAD | E18: VECES | F18: LONGITUD | G18: ANCHO | H18: ALTURA | I18: SUB-TOTAL | J18: TOTAL
B19: =+"01.08.02" -> 01.08.02 | C19: =+B3&" ("&E19&" und.)" -> VALVULA DE PURGA TIPO 2 (3 und.) | E19: =+SUM(E20:E20) -> 3
C20: =+$B$3&L20 -> VALVULA DE PURGA TIPO 2 Ø = 1" | E20: 3 | L20: Ø = 1"
B22: =B$19 & ".01" -> 01.08.02.01 | C22: TRABAJOS PRELIMINARES | E22: =+$E$19 -> 3 | L22: Descripcion | M22: Medida | N22: Unidad
B23: =B$22 & ".01" -> 01.08.02.01.01 | C23: LIMPIEZA Y DESBROCE DE TERRENO MANUAL | D23: m2 | I23: =SUM(I24:I25) -> 5.56 | J23: =+I23*$E$22 -> 16.68 | L23: Caja de Valvulas
C24: Caja de valvula | E24: 1 | F24: =+M45 -> 1.6 | G24: =+M44 -> 1.6 | I24: =+ROUND(PRODUCT(E24:G24),2) -> 2.56 | L24: Ancho | M24: 0.6 | N24: m
C25: Tuberia de limpieza | E25: 1 | F25: 3 | G25: 1 | I25: =+ROUND(PRODUCT(E25:H25),2) -> 3 | L25: Largo | M25: 0.6 | N25: m
L26: Altura | M26: 0.7 | N26: m
B27: =B$22 & ".02" -> 01.08.02.01.02 | C27: TRAZO Y REPLANTEO PRELIMINAR PARA ESTRUCTURAS | D27: m2 | I27: =SUM(I28:I29) -> 5.56 | J27: =+I27*$E$22 -> 16.68 | L27: Uña | M27: 0.1 | N27: m
C28: Caja de valvula | E28: 1 | F28: =+F24 -> 1.6 | G28: =+G24 -> 1.6 | I28: =+ROUND(PRODUCT(E28:G28),2) -> 2.56 | L28: Espesor de muro | M28: 0.1 | N28: m
C29: Tuberia de limpieza | E29: 1 | F29: =+F25 -> 3 | G29: =+G25 -> 1 | I29: =+ROUND(PRODUCT(E29:H29),2) -> 3 | L29: Cimentacion B
B31: =B$22 & ".03" -> 01.08.02.01.03 | C31: TRAZO Y REPLANTEO DURANTE EL PROCESO PARA ESTRUCTURAS | D31: m2 | I31: =SUM(I32:I33) -> 5.56 | J31: =+I31*$E$22 -> 16.68
C32: Caja de valvula | E32: 1 | F32: =+F28 -> 1.6 | G32: =+G28 -> 1.6 | I32: =+ROUND(PRODUCT(E32:G32),2) -> 2.56
C33: Tuberia de limpieza | E33: 1 | F33: =+F29 -> 3 | G33: =+G29 -> 1 | I33: =+ROUND(PRODUCT(E33:H33),2) -> 3
L34: Ancho | M34: =+M24+2*M28+2*M27 -> 1 | N34: m
B35: =B$19 & ".02" -> 01.08.02.02 | C35: MOVIMIENTO DE TIERRAS | E35: =+$E$19 -> 3 | L35: Largo | M35: =+M25+2*M28+2*M27 -> 1 | N35: m
B36: =B$35 & ".01" -> 01.08.02.02.01 | C36: EXCAVACION MANUAL EN TERRENO NORMAL | D36: m3 | I36: =SUM(I37:I44) -> 3.38 | J36: =+I36*$E$35 -> 10.14 | L36: Espesor de losa | M36: 0.1 | N36: m
C37: Caja de valvula | E37: 1 | F37: Volumen | H37: =+G42/6*((2*G38+G40)*G39+(2*G40+G38)*G41) -> 1.5786667 | I37: =+ROUND(PRODUCT(E37:H37),2) -> 1.58 | L37: Excavacion
F38: a | G38: =+M44 -> 1.6 | L38: Fondo
F39: b | G39: =+M45 -> 1.6 | L39: Excavacion | M39: 0.1 | N39: m
C40: Se considera 0.10m de | F40: a´ | G40: =+M40 -> 1.2 | L40: Ancho (a´) | M40: =+M34+2*M39 -> 1.2 | N40: m
C41: excavacion y talud 1:0.25 | F41: b´ | G41: =+M41 -> 1.2 | L41: Largo (b´) | M41: =+M35+2*M39 -> 1.2 | N41: m
F42: h | G42: =+M47 -> 0.8 | L42: Superior
L43: Excavacion | M43: =+M46*M47 -> 0.2 | N43: m
C44: Zanja para tuberia de limpieza | E44: 1 | F44: =+F25 -> 3 | G44: =+G29 -> 1 | H44: 0.6 | I44: =+ROUND(PRODUCT(E44:H44),2) -> 1.8 | L44: Ancho (a) | M44: =+M40+2*M43 -> 1.6 | N44: m
...

Sheet 1.8 M-ACERO T-02
A2: METRADOS Del SISTEMA DE AGUA POTABLE
A3: "CREACION DEL SERVICIO DE AGUA POTABLE RURAL Y CREACION DEL SERVICIO DE ALCANTARILLADO U OTRAS FORMAS DE DISPOSICION SANITARIA DE EXCRETAS EN EL SECTOR NUEVA ESPERANZA DE LA CC.NN. BAJO PITOCUNA DISTRITO DE RIO NEGRO, PROVINCIA DE SATIPO, DEPARTAMENTO DE JUNIN"
A4: VALVULA DE PURGA TIPO 2
A6: =+'[26]Captación Dique'!B140 -> 01.03.04.03 | D6: =+'[26]Captación Dique'!C140 -> ACERO f'y=4200 kg/cm2
A8: DESCRIPCION | D8: ELEMENTO | J8: Ø (Pulg.) | K8: CANTIDAD | L8: N° DE ELEMENTOS | M8: LONG. DEL ELEMENTO (m) | N8: LONGITUD (m)
N9: 1/4" | O9: 3/8" | P9: 1/2" | Q9: 5/8" | R9: 3/4" | S9: 1"
A10: CAMARA HUMEDA | B10: Muro y Losa | C10: Acero Vertical
F12: 0.95 | J12: 3/8" | K12: 4 | L12: 4 | M12: =+F12+G14 -> 1.15 | N12: =IF(+$J12=N$9,+$K12*$L12*$M12,0) -> 0 | O12: =IF(+$J12=O$9,+$K12*$L12*$M12,0) -> 18.4 | P12: =IF(+$J12=P$9,+$K12*$L12*$M12,0) -> 0 | Q12: =IF(+$J12=Q$9,+$K12*$L12*$M12,0) -> 0 | R12: =IF(+$J12=R$9,+$K12*$L12*$M12,0) -> 0 | S12: =IF(+$J12=S$9,+$K12*$L12*$M12,0) -> 0
G14: 0.2
C15: Acero Horizontal | F15: 0.2
E16: 0.2 | F16: 0.7
F17: 0.7 | H17: 0.7 | J17: 3/8" | K17: 1 | L17: 4 | M17: =+F19+H17+E16+F15+F16+F17 -> 3.2 | N17: =IF(+$J17=N$9,+$K17*$L17*$M17,0) -> 0 | O17: =IF(+$J17=O$9,+$K17*$L17*$M17,0) -> 12.8 | P17: =IF(+$J17=P$9,+$K17*$L17*$M17,0) -> 0 | Q17: =IF(+$J17=Q$9,+$K17*$L17*$M17,0) -> 0 | R17: =IF(+$J17=R$9,+$K17*$L17*$M17,0) -> 0 | S17: =IF(+$J17=S$9,+$K17*$L17*$M17,0) -> 0
F19: 0.7
C20: Losa - Acero Longitudinal y Transversal
F22: 0.92 | J22: 3/8" | K22: 4 | L22: 4 | M22: =+F22 -> 0.92 | N22: =IF(+$J22=N$9,+$K22*$L22*$M22,0) -> 0 | O22: =IF(+$J22=O$9,+$K22*$L22*$M22,0) -> 14.72 | P22: =IF(+$J22=P$9,+$K22*$L22*$M22,0) -> 0 | Q22: =IF(+$J22=Q$9,+$K22*$L22*$M22,0) -> 0 | R22: =IF(+$J22=R$9,+$K22*$L22*$M22,0) -> 0 | S22: =IF(+$J22=S$9,+$K22*$L22*$M22,0) -> 0
C25: Losa - Acero Transversal
F27: 4.44 | J27: 3/8" | K27: 0 | L27: 3 | M27: =+F27+H26+E26 -> 4.44 | N27: =IF(+$J27=N$9,+$K27*$L27*$M27,0) -> 0 | O27: =IF(+$J27=O$9,+$K27*$L27*$M27,0) -> 0 | P27: =IF(+$J27=P$9,+$K27*$L27*$M27,0) -> 0 | Q27: =IF(+$J27=Q$9,+$K27*$L27*$M27,0) -> 0 | R27: =IF(+$J27=R$9,+$K27*$L27*$M27,0) -> 0 | S27: =IF(+$J27=S$9,+$K27*$L27*$M27,0) -> 0
C30: Zapata - Acero Longitudinal
F32: 2.98 | J32: 3/8" | K32: 0 | L32: 4 | M32: =+F32 -> 2.98 | N32: =IF(+$J32=N$9,+$K32*$L32*$M32,0) -> 0 | O32: =IF(+$J32=O$9,+$K32*$L32*$M32,0) -> 0 | P32: =IF(+$J32=P$9,+$K32*$L32*$M32,0) -> 0 | Q32: =IF(+$J32=Q$9,+$K32*$L32*$M32,0) -> 0 | R32: =IF(+$J32=R$9,+$K32*$L32*$M32,0) -> 0 | S32: =IF(+$J32=S$9,+$K32*$L32*$M32,0) -> 0
C35: Zapata - Acero Transversal
F37: 4.44 | J37: 3/8" | K37: 0 | L37: 3 | M37: =+F37 -> 4.44 | N37: =IF(+$J37=N$9,+$K37*$L37*$M37,0) -> 0 | O37: =IF(+$J37=O$9,+$K37*$L37*$M37,0) -> 0 | P37: =IF(+$J37=P$9,+$K37*$L37*$M37,0) -> 0 | Q37: =IF(+$J37=Q$9,+$K37*$L37*$M37,0) -> 0 | R37: =IF(+$J37=R$9,+$K37*$L37*$M37,0) -> 0 | S37: =IF(+$J37=S$9,+$K37*$L37*$M37,0) -> 0
B40: Muro segundario | C40: Acero Vertical (interior y exterior)
F42: 1.23 | J42: 1/2" | K42: 0 | L42: 4 | M42: =+F42+G44 -> 1.33 | N42: =IF(+$J42=N$9,+$K42*$L42*$M42,0) -> 0 | O42: =IF(+$J42=O$9,+$K42*$L42*$M42,0) -> 0 | P42: =IF(+$J42=P$9,+$K42*$L42*$M42,0) -> 0 | Q42: =IF(+$J42=Q$9,+$K42*$L42*$M42,0) -> 0 | R42: =IF(+$J42=R$9,+$K42*$L42*$M42,0) -> 0 | S42: =IF(+$J42=S$9,+$K42*$L42*$M42,0) -> 0
G44: 0.1
C45: Acero Horizontal
J47: 3/8" | K47: 0 | L47: 7 | M47: =+F48 -> 0.839 | N47: =IF(+$J47=N$9,+$K47*$L47*$M47,0) -> 0 | O47: =IF(+$J47=O$9,+$K47*$L47*$M47,0) -> 0 | P47: =IF(+$J47=P$9,+$K47*$L47*$M47,0) -> 0 | Q47: =IF(+$J47=Q$9,+$K47*$L47*$M47,0) -> 0 | R47: =IF(+$J47=R$9,+$K47*$L47*$M47,0) -> 0 | S47: =IF(+$J47=S$9,+$K47*$L47*$M47,0) -> 0
F48: 0.839
C50: Zapata - Acero Longitudinal
J52: 1/2" | K52: 0 | L52: 6 | M52: =+F53 -> 0.839 | N52: =IF(+$J52=N$9,+$K52*$L52*$M52,0) -> 0 | O52: =IF(+$J52=O$9,+$K52*$L52*$M52,0) -> 0 | P52: =IF(+$J52=P$9,+$K52*$L52*$M52,0) -> 0 | Q52: =IF(+$J52=Q$9,+$K52*$L52*$M52,0) -> 0 | R52: =IF(+$J52=R$9,+$K52*$L52*$M52,0) -> 0 | S52: =IF(+$J52=S$9,+$K52*$L52*$M52,0) -> 0
F53: =+F48 -> 0.839
C55: Zapata - Acero Transversal
F57: 0.91 | J57: 1/2" | K57: 0 | L57: =+L42 -> 4 | M57: =+F57 -> 0.91 | N57: =IF(+$J57=N$9,+$K57*$L57*$M57,0) -> 0 | O57: =IF(+$J57=O$9,+$K57*$L57*$M57,0) -> 0 | P57: =IF(+$J57=P$9,+$K57*$L57*$M57,0) -> 0 | Q57: =IF(+$J57=Q$9,+$K57*$L57*$M57,0) -> 0 | R57: =IF(+$J57=R$9,+$K57*$L57*$M57,0) -> 0 | S57: =IF(+$J57=S$9,+$K57*$L57*$M57,0) -> 0
G60: 0.137
F62: 1.101 | J62: 1/2" | K62: 0 | L62: 7 | M62: =+F62+F64+G60 -> 1.488 | N62: =IF(+$J62=N$9,+$K62*$L62*$M62,0) -> 0 | O62: =IF(+$J62=O$9,+$K62*$L62*$M62,0) -> 0 | P62: =IF(+$J62=P$9,+$K62*$L62*$M62,0) -> 0 | Q62: =IF(+$J62=Q$9,+$K62*$L62*$M62,0) -> 0 | R62: =IF(+$J62=R$9,+$K62*$L62*$M62,0) -> 0 | S62: =IF(+$J62=S$9,+$K62*$L62*$M62,0) -> 0
F64: 0.25
C66: Acero Horizontal
F67: 1.26 | J67: 1/2" | K67: 0 | L67: 11 | M67: =+F67 -> 1.26 | N67: =IF(+$J67=N$9,+$K67*$L67*$M67,0) -> 0 | O67: =IF(+$J67=O$9,+$K67*$L67*$M67,0) -> 0 | P67: =IF(+$J67=P$9,+$K67*$L67*$M67,0) -> 0 | Q67: =IF(+$J67=Q$9,+$K67*$L67*$M67,0) -> 0 | R67: =IF(+$J67=R$9,+$K67*$L67*$M67,0) -> 0 | S67: =IF(+$J67=S$9,+$K67*$L67*$M67,0) -> 0
C70: Acero Vertical (Frontal) | G70: 0.2
F72: =+F67 -> 1.26 | J72: 1/2" | K72: 0 | L72: 7 | M72: =+F72+G70+G74 -> 1.96 | N72: =IF(+$J72=N$9,+$K72*$L72*$M72,0) -> 0 | O72: =IF(+$J72=O$9,+$K72*$L72*$M72,0) -> 0 | P72: =IF(+$J72=P$9,+$K72*$L72*$M72,0) -> 0 | Q72: =IF(+$J72=Q$9,+$K72*$L72*$M72,0) -> 0 | R72: =IF(+$J72=R$9,+$K72*$L72*$M72,0) -> 0 | S72: =IF(+$J72=S$9,+$K72*$L72*$M72,0) -> 0
G74: 0.5
...

Sheet 1.9 VALV-CONTROL
B1: PLANILLA DE METRADOS DE AGUA POTABLE
B2: "CREACION DEL SERVICIO DE AGUA POTABLE RURAL Y CREACION DEL SERVICIO DE ALCANTARILLADO U OTRAS FORMAS DE DISPOSICION SANITARIA DE EXCRETAS EN EL SECTOR NUEVA ESPERANZA DE LA CC.NN. BAJO PITOCUNA DISTRITO DE RIO NEGRO, PROVINCIA DE SATIPO, DEPARTAMENTO DE JUNIN"
B3: VALVULA DE CONTROL
L4: N° | M4: ACCESORIOS | N4: UNIDAD
L5: 1 | M5: Valvula compuerta Bronce | N5: 1
L6: 2 | M6: Niple PVC L=2" | N6: 2
L7: 3 | M7: Union universal PVC | N7: 2
L8: 4 | M8: Adaptador UPR PVC | N8: 2
L9: 5 | M9: Codo PVC SP x 45° | N9: 4
L10: 6 | M10: Niple PVC L=8" | N10: 2
L11: 7 | M11: Niple PVC L=7" | N11: 2
L17: VALVULA DE CONTROL (21 und.)
B18: PARTIDA | C18: DESCRIPCION | D18: UNIDAD | E18: VECES | F18: LONGITUD | G18: ANCHO | H18: ALTURA | I18: SUB-TOTAL | J18: TOTAL
B19: ="01.09" -> 01.09 | C19: =+B3&" ("&E19&" und.)" -> VALVULA DE CONTROL (6 und.) | E19: =+SUM(E20:E21) -> 6
C20: =+$B$3&L20 -> VALVULA DE CONTROL Ø = 1" | E20: 5 | L20: Ø = 1"
C21: =+$B$3&L21 -> VALVULA DE CONTROL Ø = 3/4" | E21: 1 | L21: Ø = 3/4"
B23: =B$19 & ".01" -> 01.09.01 | C23: TRABAJOS PRELIMINARES | E23: =+$E$19 -> 6 | L23: Descripcion | M23: Medida | N23: Unidad
B24: =B$23 & ".01" -> 01.09.01.01 | C24: LIMPIEZA Y DESBROCE DE TERRENO MANUAL | D24: m2 | I24: =SUM(I25) -> 2.33 | J24: =+I24*$E$23 -> 13.98 | L24: Caja de Valvulas
C25: Caja de valvula | E25: 1 | F25: =+M43 -> 1.525 | G25: =+M42 -> 1.525 | I25: =+ROUND(PRODUCT(E25:G25),2) -> 2.33 | L25: Ancho | M25: 0.6 | N25: m
L26: Largo | M26: 0.6 | N26: m
B27: =B$23 & ".02" -> 01.09.01.02 | C27: TRAZO Y REPLANTEO PRELIMINAR PARA ESTRUCTURAS | D27: m2 | I27: =SUM(I28) -> 2.33 | J27: =+I27*$E$23 -> 13.98 | L27: Altura | M27: 0.7 | N27: m
C28: Caja de valvula | E28: 1 | F28: =+F25 -> 1.525 | G28: =+G25 -> 1.525 | I28: =+ROUND(PRODUCT(E28:G28),2) -> 2.33 | L28: Uña | M28: 0.1 | N28: m
B30: =B$23 & ".03" -> 01.09.01.03 | C30: TRAZO Y REPLANTEO DURANTE EL PROCESO PARA ESTRUCTURAS | D30: m2 | I30: =SUM(I31) -> 2.33 | J30: =+I30*$E$23 -> 13.98 | L30: Espesor de muro | M30: 0.1 | N30: m
C31: Caja de valvula | E31: 1 | F31: =+F25 -> 1.525 | G31: =+G25 -> 1.525 | I31: =+ROUND(PRODUCT(E31:G31),2) -> 2.33 | L31: Cimentacion B
L32: Largo | M32: =+M26+2*M30+2*M28 -> 1 | N32: m
B33: =B$19 & ".02" -> 01.09.02 | C33: MOVIMIENTO DE TIERRAS | E33: =+$E$19 -> 6 | L33: Ancho | M33: =+M25+2*M30+2*M28 -> 1 | N33: m
B34: =B$33 & ".01" -> 01.09.02.01 | C34: EXCAVACION MANUAL EN TERRENO NORMAL | D34: m3 | I34: =SUM(I35) -> 1.21 | J34: =+I34*$E$33 -> 7.26 | L34: Espesor de losa | M34: 0.1 | N34: m
C35: Caja de valvula | E35: 1 | F35: Volumen | H35: =+G40/6*((2*G36+G38)*G37+(2*G38+G36)*G39) -> 1.2123854 | I35: =+ROUND(PRODUCT(E35:H35),2) -> 1.21 | L35: Excavacion
F36: a | G36: =+M42 -> 1.525 | L36: Fondo
F37: b | G37: =+M43 -> 1.525 | L37: Excavacion | M37: 0.1 | N37: m
C38: Se considera 0.10m de | F38: a´ | G38: =+M38 -> 1.2 | L38: Ancho (a´) | M38: =+M33+2*M37 -> 1.2 | N38: m
C39: excavacion y talud 1:0.25 | F39: b´ | G39: =+M39 -> 1.2 | L39: Largo (b´) | M39: =+M32+2*M37 -> 1.2 | N39: m
F40: h | G40: =+M45 -> 0.65 | L40: Superior
L41: Excavacion | M41: =+M44*M45 -> 0.1625 | N41: m
L42: Ancho (a) | M42: =+M38+2*M41 -> 1.525 | N42: m
B43: =B$33 & ".02" -> 01.09.02.02 | C43: RELLENO COMPACTADO CON MATERIAL PROPIO SELECCIONADO | D43: m3 | I43: =SUM(I44:I46) -> 0.66 | J43: =+I43*$E$33 -> 3.96 | L43: Largo (b) | M43: =+M39+2*M41 -> 1.525 | N43: m
C44: Volumen de excavacion | E44: 1 | H44: =+H35 -> 1.2123854 | I44: =+ROUND(PRODUCT(E44:H44),2) -> 1.21 | L44: Talud | M44: 0.25 | N44: m
C45: Volumen de muros | E45: -1 | F45: =+M26+2*M30 -> 0.8 | G45: =+M25+2*M30 -> 0.8 | H45: =+M27 -> 0.7 | I45: =+ROUND(PRODUCT(E45:H45),2) -> -0.45 | L45: Altura (h) | M45: =+M27-M46 -> 0.65 | N45: m
C46: Volumen de losa | E46: -1 | F46: =+M33 -> 1 | G46: =+M32 -> 1 | H46: =+M34 -> 0.1 | I46: =+ROUND(PRODUCT(E46:H46),2) -> -0.1 | L46: Superficie Libre (sl) | M46: 0.05 | N46: m
L47: Filtro de piedra | M47: 0.2 | N47: m
...

Sheet 1.9 M-Acero
B3: HOJA DE METRADOS DE AGUA POTABLE
B4: "CREACION DEL SERVICIO DE AGUA POTABLE RURAL Y CREACION DEL SERVICIO DE ALCANTARILLADO U OTRAS FORMAS DE DISPOSICION SANITARIA DE EXCRETAS EN EL SECTOR NUEVA ESPERANZA DE LA CC.NN. BAJO PITOCUNA DISTRITO DE RIO NEGRO, PROVINCIA DE SATIPO, DEPARTAMENTO DE JUNIN
B7: METRADO DE VALVULA DE CONTROL
B9: =+'[26]Captación Dique'!B141 -> 0 | E9: =+'[26]Captación Dique'!C141 -> Ver Planilla de Metrados de Acero
B11: DESCRIPCION | E11: ELEMENTO | K11: Ø (Pulg.) | L11: CANTIDAD | M11: N° DE ELEMENTOS | N11: LONG. DEL ELEMENTO (m) | O11: LONGITUD (m)
O12: 1/4" | P12: 3/8" | Q12: 1/2" | R12: 5/8" | S12: 3/4" | T12: 1"
B13: CAMARA HUMEDA | C13: Muro y Losa | D13: Acero Vertical
G15: 0.95 | K15: 3/8" | L15: 4 | M15: 4 | N15: =+G15+H17 -> 1.15 | O15: =IF(+$K15=O$11,+$L15*$M15*$N15,0) -> 0 | P15: =IF(+$K15=P$12,+$L15*$M15*$N15,0) -> 18.4 | Q15: =IF(+$K15=Q$11,+$L15*$M15*$N15,0) -> 0 | R15: =IF(+$K15=R$11,+$L15*$M15*$N15,0) -> 0 | S15: =IF(+$K15=S$11,+$L15*$M15*$N15,0) -> 0 | T15: =IF(+$K15=T$11,+$L15*$M15*$N15,0) -> 0
H17: 0.2
D18: Acero Horizontal | G18: 0.2
F19: 0.2 | G19: 0.7
G20: 0.7 | I20: 0.7 | K20: 3/8" | L20: 1 | M20: 4 | N20: =+G22+I20+F19+G18+G19+G20 -> 3.2 | O20: =IF(+$K20=O$11,+$L20*$M20*$N20,0) -> 0 | P20: =IF(+$K20=P$12,+$L20*$M20*$N20,0) -> 12.8 | Q20: =IF(+$K20=Q$11,+$L20*$M20*$N20,0) -> 0 | R20: =IF(+$K20=R$11,+$L20*$M20*$N20,0) -> 0 | S20: =IF(+$K20=S$11,+$L20*$M20*$N20,0) -> 0 | T20: =IF(+$K20=T$11,+$L20*$M20*$N20,0) -> 0
G22: 0.7
D23: Losa - Acero Longitudinal y Transversal
G25: 0.92 | K25: 3/8" | L25: 4 | M25: 4 | N25: =+G25 -> 0.92 | O25: =IF(+$K25=O$11,+$L25*$M25*$N25,0) -> 0 | P25: =IF(+$K25=P$12,+$L25*$M25*$N25,0) -> 14.72 | Q25: =IF(+$K25=Q$11,+$L25*$M25*$N25,0) -> 0 | R25: =IF(+$K25=R$11,+$L25*$M25*$N25,0) -> 0 | S25: =IF(+$K25=S$11,+$L25*$M25*$N25,0) -> 0 | T25: =IF(+$K25=T$11,+$L25*$M25*$N25,0) -> 0
D28: Losa - Acero Transversal
G30: 4.44 | K30: 3/8" | L30: 0 | M30: 3 | N30: =+G30+I29+F29 -> 4.44 | O30: =IF(+$K30=O$11,+$L30*$M30*$N30,0) -> 0 | P30: =IF(+$K30=P$11,+$L30*$M30*$N30,0) -> 0 | Q30: =IF(+$K30=Q$11,+$L30*$M30*$N30,0) -> 0 | R30: =IF(+$K30=R$11,+$L30*$M30*$N30,0) -> 0 | S30: =IF(+$K30=S$11,+$L30*$M30*$N30,0) -> 0 | T30: =IF(+$K30=T$11,+$L30*$M30*$N30,0) -> 0
D33: Zapata - Acero Longitudinal
G35: 2.98 | K35: 3/8" | L35: 0 | M35: 4 | N35: =+G35 -> 2.98 | O35: =IF(+$K35=O$11,+$L35*$M35*$N35,0) -> 0 | P35: =IF(+$K35=P$11,+$L35*$M35*$N35,0) -> 0 | Q35: =IF(+$K35=Q$11,+$L35*$M35*$N35,0) -> 0 | R35: =IF(+$K35=R$11,+$L35*$M35*$N35,0) -> 0 | S35: =IF(+$K35=S$11,+$L35*$M35*$N35,0) -> 0 | T35: =IF(+$K35=T$11,+$L35*$M35*$N35,0) -> 0
D38: Zapata - Acero Transversal
G40: 4.44 | K40: 3/8" | L40: 0 | M40: 3 | N40: =+G40 -> 4.44 | O40: =IF(+$K40=O$11,+$L40*$M40*$N40,0) -> 0 | P40: =IF(+$K40=P$11,+$L40*$M40*$N40,0) -> 0 | Q40: =IF(+$K40=Q$11,+$L40*$M40*$N40,0) -> 0 | R40: =IF(+$K40=R$11,+$L40*$M40*$N40,0) -> 0 | S40: =IF(+$K40=S$11,+$L40*$M40*$N40,0) -> 0 | T40: =IF(+$K40=T$11,+$L40*$M40*$N40,0) -> 0
C43: Muro segundario | D43: Acero Vertical (interior y exterior)
G45: 1.23 | K45: 1/2" | L45: 0 | M45: 4 | N45: =+G45+H47 -> 1.33 | O45: =IF(+$K45=O$11,+$L45*$M45*$N45,0) -> 0 | P45: =IF(+$K45=P$11,+$L45*$M45*$N45,0) -> 0 | Q45: =IF(+$K45=Q$11,+$L45*$M45*$N45,0) -> 0 | R45: =IF(+$K45=R$11,+$L45*$M45*$N45,0) -> 0 | S45: =IF(+$K45=S$11,+$L45*$M45*$N45,0) -> 0 | T45: =IF(+$K45=T$11,+$L45*$M45*$N45,0) -> 0
H47: 0.1
D48: Acero Horizontal
K50: 3/8" | L50: 0 | M50: 7 | N50: =+G51 -> 0.839 | O50: =IF(+$K50=O$11,+$L50*$M50*$N50,0) -> 0 | P50: =IF(+$K50=P$11,+$L50*$M50*$N50,0) -> 0 | Q50: =IF(+$K50=Q$11,+$L50*$M50*$N50,0) -> 0 | R50: =IF(+$K50=R$11,+$L50*$M50*$N50,0) -> 0 | S50: =IF(+$K50=S$11,+$L50*$M50*$N50,0) -> 0 | T50: =IF(+$K50=T$11,+$L50*$M50*$N50,0) -> 0
G51: 0.839
D53: Zapata - Acero Longitudinal
K55: 1/2" | L55: 0 | M55: 6 | N55: =+G56 -> 0.839 | O55: =IF(+$K55=O$11,+$L55*$M55*$N55,0) -> 0 | P55: =IF(+$K55=P$11,+$L55*$M55*$N55,0) -> 0 | Q55: =IF(+$K55=Q$11,+$L55*$M55*$N55,0) -> 0 | R55: =IF(+$K55=R$11,+$L55*$M55*$N55,0) -> 0 | S55: =IF(+$K55=S$11,+$L55*$M55*$N55,0) -> 0 | T55: =IF(+$K55=T$11,+$L55*$M55*$N55,0) -> 0
G56: =+G51 -> 0.839
D58: Zapata - Acero Transversal
G60: 0.91 | K60: 1/2" | L60: 0 | M60: =+M45 -> 4 | N60: =+G60 -> 0.91 | O60: =IF(+$K60=O$11,+$L60*$M60*$N60,0) -> 0 | P60: =IF(+$K60=P$11,+$L60*$M60*$N60,0) -> 0 | Q60: =IF(+$K60=Q$11,+$L60*$M60*$N60,0) -> 0 | R60: =IF(+$K60=R$11,+$L60*$M60*$N60,0) -> 0 | S60: =IF(+$K60=S$11,+$L60*$M60*$N60,0) -> 0 | T60: =IF(+$K60=T$11,+$L60*$M60*$N60,0) -> 0
H63: 0.137
G65: 1.101 | K65: 1/2" | L65: 0 | M65: 7 | N65: =+G65+G67+H63 -> 1.488 | O65: =IF(+$K65=O$11,+$L65*$M65*$N65,0) -> 0 | P65: =IF(+$K65=P$11,+$L65*$M65*$N65,0) -> 0 | Q65: =IF(+$K65=Q$11,+$L65*$M65*$N65,0) -> 0 | R65: =IF(+$K65=R$11,+$L65*$M65*$N65,0) -> 0 | S65: =IF(+$K65=S$11,+$L65*$M65*$N65,0) -> 0 | T65: =IF(+$K65=T$11,+$L65*$M65*$N65,0) -> 0
G67: 0.25
D69: Acero Horizontal
G70: 1.26 | K70: 1/2" | L70: 0 | M70: 11 | N70: =+G70 -> 1.26 | O70: =IF(+$K70=O$11,+$L70*$M70*$N70,0) -> 0 | P70: =IF(+$K70=P$11,+$L70*$M70*$N70,0) -> 0 | Q70: =IF(+$K70=Q$11,+$L70*$M70*$N70,0) -> 0 | R70: =IF(+$K70=R$11,+$L70*$M70*$N70,0) -> 0 | S70: =IF(+$K70=S$11,+$L70*$M70*$N70,0) -> 0 | T70: =IF(+$K70=T$11,+$L70*$M70*$N70,0) -> 0
D73: Acero Vertical (Frontal) | H73: 0.2
G75: =+G70 -> 1.26 | K75: 1/2" | L75: 0 | M75: 7 | N75: =+G75+H73+H77 -> 1.96 | O75: =IF(+$K75=O$11,+$L75*$M75*$N75,0) -> 0 | P75: =IF(+$K75=P$11,+$L75*$M75*$N75,0) -> 0 | Q75: =IF(+$K75=Q$11,+$L75*$M75*$N75,0) -> 0 | R75: =IF(+$K75=R$11,+$L75*$M75*$N75,0) -> 0 | S75: =IF(+$K75=S$11,+$L75*$M75*$N75,0) -> 0 | T75: =IF(+$K75=T$11,+$L75*$M75*$N75,0) -> 0
H77: 0.5
...

Sheet 1.10 CRUCE AEREO 2.50 M
A1: PLANILLA DE METRADOS DE AGUA POTABLE
A2: PROYECTO: | B2: "CREACION DEL SERVICIO DE AGUA POTABLE RURAL Y CREACION DEL SERVICIO DE ALCANTARILLADO U OTRAS FORMAS DE DISPOSICION SANITARIA DE EXCRETAS EN EL SECTOR NUEVA ESPERANZA DE LA CC.NN. BAJO PITOCUNA DISTRITO DE RIO NEGRO, PROVINCIA DE SATIPO, DEPARTAMENTO DE JUNIN"
A4: CRUCE AEREO DE CONCRETO EN ZANJAS L= 2.50 m
A5: 1.15 | B5: PASE AEREO | D5: L= | E5: 4 | H5: PLANO : | I5: AP
A7: ITEM | B7: DESCRIPCION | C7: UND | D7: CANT. | E7: DIMENSIONES | H7: PARCIAL | I7: TOTAL
E8: LARGO | F8: ANCHO | G8: ALTO
A9: 1.1 | B9: CRUCE EN ZANJAS DE VIGA DE CONCRETO ARMADO (01 UND)
A10: =+"01.10" -> 01.10 | B10: CRUCE AEREOS EN ZANJAS DE 2.5m (1 und) | D10: 1
