Workbook
Name __PP1: '[1]Red 12Piletas'!$E$99
Name __PP1: '[2]Red 12Piletas'!$E$99
Name __PP10: '[1]Red 12Piletas'!$E$127
Name __PP10: '[2]Red 12Piletas'!$E$127
Name __PP11: '[1]Red 12Piletas'!$E$131
Name __PP11: '[2]Red 12Piletas'!$E$131
Name __PP12: '[1]Red 12Piletas'!$E$135
Name __PP12: '[2]Red 12Piletas'!$E$135
Name __PP2: '[1]Red 12Piletas'!$E$102
Name __PP2: '[2]Red 12Piletas'!$E$102
Name __PP3: '[1]Red 12Piletas'!$E$105
Name __PP3: '[2]Red 12Piletas'!$E$105
Name __PP4: '[1]Red 12Piletas'!$E$108
Name __PP4: '[2]Red 12Piletas'!$E$108
Name __PP5: '[1]Red 12Piletas'!$E$112
Name __PP5: '[2]Red 12Piletas'!$E$112
Name __PP6: '[1]Red 12Piletas'!$E$115
Name __PP6: '[2]Red 12Piletas'!$E$115
Name __PP7: '[1]Red 12Piletas'!$E$118
Name __PP7: '[2]Red 12Piletas'!$E$118
Name __PP8: '[1]Red 12Piletas'!$E$121
Name __PP8: '[2]Red 12Piletas'!$E$121
Name __PP9: '[1]Red 12Piletas'!$E$124
Name __PP9: '[2]Red 12Piletas'!$E$124
Name _PP1: '[1]Red 12Piletas'!$E$99
Name _PP1: '[2]Red 12Piletas'!$E$99
Name _PP10: '[1]Red 12Piletas'!$E$127
Name _PP10: '[2]Red 12Piletas'!$E$127
Name _PP11: '[1]Red 12Piletas'!$E$131
Name _PP11: '[2]Red 12Piletas'!$E$131
Name _PP12: '[1]Red 12Piletas'!$E$135
Name _PP12: '[2]Red 12Piletas'!$E$135
Name _PP2: '[1]Red 12Piletas'!$E$102
Name _PP2: '[2]Red 12Piletas'!$E$102
Name _PP3: '[1]Red 12Piletas'!$E$105
Name _PP3: '[2]Red 12Piletas'!$E$105
Name _PP4: '[1]Red 12Piletas'!$E$108
Name _PP4: '[2]Red 12Piletas'!$E$108
Name _PP5: '[1]Red 12Piletas'!$E$112
Name _PP5: '[2]Red 12Piletas'!$E$112
Name _PP6: '[1]Red 12Piletas'!$E$115
Name _PP6: '[2]Red 12Piletas'!$E$115
Name _PP7: '[1]Red 12Piletas'!$E$118
Name _PP7: '[2]Red 12Piletas'!$E$118
Name _PP8: '[1]Red 12Piletas'!$E$121
Name _PP8: '[2]Red 12Piletas'!$E$121
Name _PP9: '[1]Red 12Piletas'!$E$124
Name _PP9: '[2]Red 12Piletas'!$E$124
Name A: #REF!
Name A: #REF!
Name B: #REF!
Name B: #REF!
Name B: #REF!
Name captac2: #REF!
Name captac2: #REF!
Name COSTO2.03.01: '[3]Cuadro Nº06-C.U.'!#REF!
Name COSTO2.03.01: '[3]Cuadro Nº06-C.U.'!#REF!
Name COSTO2.03.02: '[3]Cuadro Nº06-C.U.'!#REF!
Name COSTO2.03.02: '[3]Cuadro Nº06-C.U.'!#REF!
Name COSTO2.05: '[3]Cuadro Nº06-C.U.'!#REF!

Sheet UBS AH
B2: PLANILLA DE METRADOS DE SANEAMIENTO
B3: "CREACION DEL SERVICIO DE AGUA POTABLE RURAL Y CREACION DEL SERVICIO DE ALCANTARILLADO U OTRAS FORMAS DE DISPOSICION SANITARIA DE EXCRETAS EN EL SECTOR NUEVA ESPERANZA DE LA CC.NN. BAJO PITUCUNA DISTRITO DE RIO NEGRO, PROVINCIA DE SATIPO, DEPARTAMENTO DE JUNIN"
B4: UBS - AH PARA I.E. PRIMARIA
B24: PARTIDA | C24: DESCRIPCION | D24: UNID. | E24: VECES | F24: LONG. | G24: ANCHO | H24: ALTURA | I24: SUB-TOTAL | J24: TOTAL
B25: 02 | C25: SISTEMA DE SANEAMIENTO
B26: =+B25 &".03.01" -> 02.03.01 | C26: ="UBS AH PARA I.E. PRIMARIA ("&1&" und)" -> UBS AH PARA I.E. PRIMARIA (1 und)
B27: =+B26 &".01" -> 02.03.01.01 | C27: ESTRUCTURAS
B28: =$B$27 & ".01" -> 02.03.01.01.01 | C28: TRABAJOS PRELIMINARES | E28: 1
B29: =$B$28 & ".01" -> 02.03.01.01.01.01 | C29: LIMPIEZA DE TERRENO MANUAL | D29: m2 | I29: =+SUM(I30:I31) -> 18.52 | J29: =+$E$28*I29 -> 18.52
C30: Caseta UBS | E30: 1 | F30: 5.1 | G30: 1.6 | I30: =+ROUND(PRODUCT(E30:H30),2) -> 8.16
C31: Vereda | E31: 1 | F31: area | G31: 10.3632 | I31: =+ROUND(PRODUCT(E31:H31),2) -> 10.36
B33: =$B$28 & ".02" -> 02.03.01.01.01.02 | C33: TRAZO Y REPLANTEO INICIAL EN ESTRUCTURAS DE CASETA | D33: m2 | I33: =+SUM(I34:I35) -> 18.52 | J33: =+$E$28*I33 -> 18.52
C34: Caseta UBS | E34: 1 | F34: =F30 -> 5.1 | G34: =G30 -> 1.6 | I34: =+ROUND(PRODUCT(E34:H34),2) -> 8.16
C35: Vereda | E35: 1 | F35: area | G35: =G31 -> 10.3632 | I35: =+ROUND(PRODUCT(E35:H35),2) -> 10.36
B37: =$B$28 & ".03" -> 02.03.01.01.01.03 | C37: TRAZO Y REPLANTEO DURANTE PROCESO EN ESTRUCTURAS DE CASETA | D37: m2 | I37: =+SUM(I38:I39) -> 18.52 | J37: =+$E$28*I37 -> 18.52
C38: Caseta UBS | E38: 1 | F38: =F34 -> 5.1 | G38: =G34 -> 1.6 | I38: =+ROUND(PRODUCT(E38:H38),2) -> 8.16
C39: Vereda | E39: 1 | F39: area | G39: =G35 -> 10.3632 | I39: =+ROUND(PRODUCT(E39:H39),2) -> 10.36
B41: =$B$27 & ".02" -> 02.03.01.01.02 | C41: MOVIMIENTO DE TIERRAS | E41: =E28 -> 1
B42: =$B$41 & ".01" -> 02.03.01.01.02.01 | C42: EXCAVACION MANUAL EN TERRENO NORMAL | D42: m3 | I42: =SUM(I43:I47) -> 5.84 | J42: =+$E$41*I42 -> 5.84
C43: Piso de la caseta | E43: 3 | F43: 1.05 | G43: 1.25 | H43: 0.2 | I43: =+ROUND(PRODUCT(E43:H43),2) -> 0.79
C44: Excavación manual de zanjas para cimientos corridos
C45: CC-01 (0.40 x 0.50)- EJE 1-1 Y EJE 2-2 | E45: 2 | F45: 5.35 | G45: 0.4 | H45: 0.5 | I45: =+ROUND(PRODUCT(E45:H45),2) -> 2.14
C46: CC-01 (0.40 x 0.50)-EJE A-A, EJE B-B, EJE C-C Y EJE D-D | E46: 4 | F46: 1.05 | G46: 0.4 | H46: 0.5 | I46: =+ROUND(PRODUCT(E46:H46),2) -> 0.84
C47: Vereda | E47: 1 | F47: area | G47: =G39 -> 10.3632 | H47: 0.2 | I47: =+ROUND(PRODUCT(E47:H47),2) -> 2.07
B49: =$B$41 & ".02" -> 02.03.01.01.02.02 | C49: NIVELACION INTERIOR Y APISONADO (MANUAL) | D49: m2 | I49: =SUM(I50:I51) -> 18.52 | J49: =+$E$41*I49 -> 18.52
C50: Caseta UBS | E50: 1 | F50: =F30 -> 5.1 | G50: =G30 -> 1.6 | I50: =+ROUND(PRODUCT(E50:H50),2) -> 8.16
C51: Vereda | E51: 1 | F51: area | G51: =G31 -> 10.3632 | I51: =+ROUND(PRODUCT(E51:H51),2) -> 10.36
B53: =$B$41 & ".03" -> 02.03.01.01.02.03 | C53: RELLENO CON MATERIAL PROPIO SELECCIONADO | I53: =I54+I55+I56 -> 1.11 | J53: =I53*E41 -> 1.11
C54: Piso de la Caseta UBS | E54: 3 | F54: 1.05 | G54: 1.25 | H54: 0.1 | I54: =+ROUND(PRODUCT(E54:H54),2) -> 0.39
C55: Vereda | E55: 1 | F55: area | G55: 0.01 | H55: 12.2 | I55: =+ROUND(PRODUCT(E55:H55),2) -> 0.12
F56: area | G56: 0.105 | H56: 5.7 | I56: =+ROUND(PRODUCT(E56:H56),2) -> 0.6
B58: =$B$41 & ".04" -> 02.03.01.01.02.04 | C58: ACARREO Y ELIMINACION DE MAT. EXCEDENTE Dmax=30 m | D58: m3 | I58: =SUM(I60:I62) -> 5.52 | J58: =I58 -> 5.52
G59: vol. | H59: F.Espjm
C60: Vol.= vol. Excavacion de terreno suelto 85% | E60: 1 | F60: 0.85 | G60: =J42 -> 5.84 | H60: 1.15 | I60: =+ROUND(PRODUCT(E60:H60),2) -> 5.71
C61: Vol.= vol. Excavacion de boloneria 15% | E61: 1 | F61: 0.15 | G61: =J42 -> 5.84 | H61: 1.3 | I61: =+ROUND(PRODUCT(E61:H61),2) -> 1.14
C62: Vol rellenado | E62: -1 | G62: =J53 -> 1.11 | H62: 1.2 | I62: =+ROUND(PRODUCT(E62:H62),2) -> -1.33
B64: =$B$27 & ".03" -> 02.03.01.01.03 | C64: OBRAS DE CONCRETO SIMPLE | E64: =E28 -> 1
B65: =$B$64 & ".01" -> 02.03.01.01.03.01 | C65: CONCRETO EN CIMIENTOS C:H 1:10+30% PG | D65: m3 | I65: =SUM(I66:I67) -> 2.98 | J65: =+$E$64*I65 -> 2.98
C66: CC-01 (0.40 x 0.50)- EJE 1-1 Y 2-2 | E66: 2 | F66: 5.35 | G66: 0.4 | H66: 0.5 | I66: =+ROUND(PRODUCT(E66:H66),2) -> 2.14
C67: CC-01 (0.40 x 0.50)-EJE A-A, B-B, C-C Y D-D | E67: 4 | F67: 1.05 | G67: 0.4 | H67: 0.5 | I67: =+ROUND(PRODUCT(E67:H67),2) -> 0.84
...

Sheet Metrado de Acero
B2: HOJA DE METRADOS DE SANEAMIENTO
B4: =+'UBS AH'!B3:J3 -> "CREACION DEL SERVICIO DE AGUA POTABLE RURAL Y CREACION DEL SERVICIO DE ALCANTARILLADO U OTRAS FORMAS DE DISPOSICION SANITARIA DE EXCRETAS EN EL SECTOR NUEVA ESPERANZA DE LA CC.NN. BAJO PITUCUNA DISTRITO DE RIO NEGRO, PROVINCIA DE SATIPO, DEPARTAMENTO DE JUNIN"
B6: =+"METRADO DE ACERO DE "&'UBS AH'!B4:J4 -> METRADO DE ACERO DE UBS - AH PARA I.E. PRIMARIA
B8: =+'UBS AH'!B107 -> 02.03.01.01.04.05 | D8: =+'UBS AH'!C107 -> ACERO CORRUGADO f'y=4200 kg/cm2 G-60 EN CASETA DE UBS | H8: CASETA UBS
B10: DESCRIPCION | D10: ELEMENTO | J10: Ø (Pulg.) | K10: CANTIDAD | L10: N° DE ELEMENTOS | M10: LONG. DEL ELEMENTO (m) | N10: LONGITUD (m)
N11: 1/4" | O11: 3/8" | P11: 1/2" | Q11: 5/8" | R11: 3/4" | S11: 1"
B12: Zapata | C12: Longitudinal
J13: 3/8" | K13: 4 | L13: 3 | M13: =+F14 -> 0.28 | N13: =IF(+$J13=N$11,+$K13*$L13*$M13,0) -> 0 | O13: =IF(+$J13=O$11,+$K13*$L13*$M13,0) -> 3.36 | P13: =IF(+$J13=P$11,+$K13*$L13*$M13,0) -> 0 | Q13: =IF(+$J13=Q$11,+$K13*$L13*$M13,0) -> 0 | R13: =IF(+$J13=R$11,+$K13*$L13*$M13,0) -> 0 | S13: =IF(+$J13=S$11,+$K13*$L13*$M13,0) -> 0
F14: 0.28
C16: Transversal
J17: 3/8" | K17: =+K13 -> 4 | L17: 11 | M17: =+F18 -> 0.28 | N17: =IF(+$J17=N$11,+$K17*$L17*$M17,0) -> 0 | O17: =IF(+$J17=O$11,+$K17*$L17*$M17,0) -> 12.32
F18: 0.28 | P18: =IF(+$J17=P$11,+$K17*$L17*$M17,0) -> 0 | Q18: =IF(+$J17=Q$11,+$K17*$L17*$M17,0) -> 0 | R18: =IF(+$J17=R$11,+$K17*$L17*$M17,0) -> 0 | S18: =IF(+$J17=S$11,+$K17*$L17*$M17,0) -> 0
C20: Estribos
F22: 0.05
G23: 0.1 | J23: 1/4" | K23: =+K13 -> 4 | L23: 3 | M23: =+F26*2+G23*2+F22*2 -> 0.5 | N23: =IF(+$J23=N$11,+$K23*$L23*$M23,0) -> 6 | O23: =IF(+$J23=O$11,+$K23*$L23*$M23,0) -> 0
F26: 0.1 | P26: =IF(+$J23=P$11,+$K23*$L23*$M23,0) -> 0 | Q26: =IF(+$J23=Q$11,+$K23*$L23*$M23,0) -> 0 | R26: =IF(+$J23=R$11,+$K23*$L23*$M23,0) -> 0 | S26: =IF(+$J23=S$11,+$K23*$L23*$M23,0) -> 0
B28: Columnas | C28: Vertical
G29: 0.16
J31: 3/8" | K31: =+K13 -> 4 | L31: 4 | M31: =+F34+G32+G29 -> 3.32 | N31: =IF(+$J31=N$11,+$K31*$L31*$M31,0) -> 0 | O31: =IF(+$J31=O$11,+$K31*$L31*$M31,0) -> 53.12 | P31: =IF(+$J31=P$11,+$K31*$L31*$M31,0) -> 0 | Q31: =IF(+$J31=Q$11,+$K31*$L31*$M31,0) -> 0 | R31: =IF(+$J31=R$11,+$K31*$L31*$M31,0) -> 0 | S31: =IF(+$J31=S$11,+$K31*$L31*$M31,0) -> 0
G32: 3.09
F34: 0.07
C36: Estribos
F38: 0.05
G39: 0.1 | J39: 1/4" | K39: =+K31 -> 4 | L39: 18 | M39: =+F41*2+G39*2+F38*2 -> 0.5 | N39: =IF(+$J39=N$11,+$K39*$L39*$M39,0) -> 36 | O39: =IF(+$J39=O$11,+$K39*$L39*$M39,0) -> 0
F41: 0.1 | P41: =IF(+$J39=P$11,+$K39*$L39*$M39,0) -> 0 | Q41: =IF(+$J39=Q$11,+$K39*$L39*$M39,0) -> 0 | R41: =IF(+$J39=R$11,+$K39*$L39*$M39,0) -> 0 | S41: =IF(+$J39=S$11,+$K39*$L39*$M39,0) -> 0
B43: Vigas V-1 | C43: Horizontal
F44: 3.07
J45: 3/8" | K45: 4 | L45: 2 | M45: =+E46+G46+F44 -> 3.39 | N45: =IF(+$J45=N$11,+$K45*$L45*$M45,0) -> 0 | O45: =IF(+$J45=O$11,+$K45*$L45*$M45,0) -> 27.12 | P45: =IF(+$J45=P$11,+$K45*$L45*$M45,0) -> 0 | Q45: =IF(+$J45=Q$11,+$K45*$L45*$M45,0) -> 0 | R45: =IF(+$J45=R$11,+$K45*$L45*$M45,0) -> 0 | S45: =IF(+$J45=S$11,+$K45*$L45*$M45,0) -> 0
E46: 0.16 | G46: 0.16
C48: Estribos
G50: 0.35
J51: 1/4" | K51: =+K45 -> 4 | L51: 21 | M51: =+G50 -> 0.35 | N51: =IF(+$J51=N$11,+$K51*$L51*$M51,0) -> 29.4 | O51: =IF(+$J51=O$11,+$K51*$L51*$M51,0) -> 0
B53: Vigas V-2 | C53: Horizontal
F54: 2.22
J55: 3/8" | K55: 4 | L55: 2 | M55: =+E56+G56+F54 -> 2.54 | N55: =IF(+$J55=N$11,+$K55*$L55*$M55,0) -> 0 | O55: =IF(+$J55=O$11,+$K55*$L55*$M55,0) -> 20.32 | P55: =IF(+$J55=P$11,+$K55*$L55*$M55,0) -> 0 | Q55: =IF(+$J55=Q$11,+$K55*$L55*$M55,0) -> 0 | R55: =IF(+$J55=R$11,+$K55*$L55*$M55,0) -> 0 | S55: =IF(+$J55=S$11,+$K55*$L55*$M55,0) -> 0
E56: 0.16 | G56: 0.16
C58: Estribos
G60: 0.35
J61: 1/4" | K61: =+K55 -> 4 | L61: 17 | M61: =+G60 -> 0.35 | N61: =IF(+$J61=N$11,+$K61*$L61*$M61,0) -> 23.8 | O61: =IF(+$J61=O$11,+$K61*$L61*$M61,0) -> 0
P62: =IF(+$J61=P$11,+$K61*$L61*$M61,0) -> 0 | Q62: =IF(+$J61=Q$11,+$K61*$L61*$M61,0) -> 0 | R62: =IF(+$J61=R$11,+$K61*$L61*$M61,0) -> 0 | S62: =IF(+$J61=S$11,+$K61*$L61*$M61,0) -> 0
...

Sheet UBS TRATAMIENTO
B2: PLANILLA DE METRADOS DEL SISTEMA DE SANEAMIENTO
B3: "CREACION DEL SERVICIO DE AGUA POTABLE RURAL Y CREACION DEL SERVICIO DE ALCANTARILLADO U OTRAS FORMAS DE DISPOSICION SANITARIA DE EXCRETAS EN EL SECTOR NUEVA ESPERANZA DE LA CC.NN. BAJO PITUCUNA DISTRITO DE RIO NEGRO, PROVINCIA DE SATIPO, DEPARTAMENTO DE JUNIN"
B4: UBS - ARRASTRE HIDRAULICO PARA I.E. PRIMARIA
B19: PARTIDA | C19: DESCRIPCION | D19: UNID. | E19: VECES | F19: LONG. | G19: ANCHO | H19: ALTURA | I19: SUB-TOTAL | J19: TOTAL
B20: 02.03.02 | C20: BIODIGESTOR DE 1300 LTS PARA I.E. PRIMARIA
B21: =$B$20 & ".01" -> 02.03.02.01 | C21: TRABAJOS PRELIMINARES | E21: ='[6]UBS AH'!E30 -> 1
B22: =$B$21 & ".01" -> 02.03.02.01.01 | C22: LIMPIEZA DE TERRENO MANUAL | D22: m2 | I22: =+SUM(I23:I23) -> 4.15 | J22: =I22*E21 -> 4.15
E23: 1 | F23: area | G23: 4.1548 | I23: =+ROUND(PRODUCT(E23:H23),2) -> 4.15
B25: =$B$21 & ".02" -> 02.03.02.01.02 | C25: TRAZO Y REPLANTEO PRELIMINAR PARA ESTRUCTURAS | D25: m2 | I25: =+SUM(I26) -> 4.15 | J25: =I25*E21 -> 4.15
E26: 1 | F26: =F23 -> area | G26: =G23 -> 4.1548 | I26: =+ROUND(PRODUCT(E26:H26),2) -> 4.15
B28: =$B$21 & ".03" -> 02.03.02.01.03 | C28: TRAZO Y REPLANTEO DURANTE EL PROCESO PARA ESTRUCTURAS | D28: m2 | I28: =+SUM(I29) -> 4.15 | J28: =I28*E21 -> 4.15
E29: 1 | F29: =F26 -> area | G29: =G26 -> 4.1548 | I29: =+ROUND(PRODUCT(E29:H29),2) -> 4.15
B31: =$B$20 & ".02" -> 02.03.02.02 | C31: MOVIMIENTO DE TIERRAS | E31: =E21 -> 1
B32: =$B$31 & ".01" -> 02.03.02.02.01 | C32: EXCAVACION MANUAL EN TERRENO NORMAL | D32: m3 | I32: =+SUM(I33:I34) -> 5.37 | J32: =I32*E21 -> 5.37
C33: Solado | E33: 1 | F33: =F29 -> area | G33: 1.55 | H33: 0.1 | I33: =+ROUND(PRODUCT(E33:H33),2) -> 0.16
C34: Volumen cono truncado V = (1/3) * π * h * (r² + r * R + R²) | E34: 1 | F34: Volumen | G34: =0.333333333333333*PI()*G37*(G36*G36+G35*G35+G36*G35) -> 5.207394 | I34: =+ROUND(PRODUCT(E34:H34),2) -> 5.21
F35: r | G35: 0.6
F36: R | G36: 1.21
F37: h | G37: 1.95 | L37: =1.5*2 -> 3
B39: =$B$31 & ".02" -> 02.03.02.02.02 | C39: REFINE Y COMPACTACION DE FONDOS | D39: m2 | I39: =+SUM(I40) -> 1.55 | J39: =I39*E21 -> 1.55
E40: 1 | F40: =F33 -> area | G40: =G33 -> 1.55 | I40: =+ROUND(PRODUCT(E40:H40),2) -> 1.55
B42: =$B$31 & ".03" -> 02.03.02.02.03 | C42: RELLENO COMPACTADO CON MATERIAL PROPIO SELECCIONADO | D42: m3 | I42: =+SUM(I43:I45) -> 2.8125 | J42: =I42*E21 -> 2.8125
C43: Volumen excavado | E43: 1 | F43: Volumen | G43: =+I34 -> 5.21 | I43: =+PRODUCT(E43:H43) -> 5.21
C44: Volumen del biodigestor | E44: -1 | F44: Area= | G44: 1.15 | H44: 1.95 | I44: =+PRODUCT(E44:H44) -> -2.2425
C45: Volumen de la losa | E45: -1 | F45: Area= | G45: 1.55 | H45: 0.1 | I45: =+PRODUCT(E45:H45) -> -0.155
B47: =$B$31 & ".04" -> 02.03.02.02.04 | C47: ACARREO Y ELIMINACION DE DMATERIAL EXCEDENTE | D47: m2 | F47: fac. de esp. | I47: =+SUM(I48) -> 3.2 | J47: =I47*E21 -> 3.2
E48: 1 | F48: 1.25 | G48: =I32-I42 -> 2.5575 | I48: =+ROUND(PRODUCT(E48:H48),2) -> 3.2
B50: =$B$20 & ".03" -> 02.03.02.03 | C50: OBRAS DE CONCRETO SIMPLE | E50: =E31 -> 1
B51: =$B$50 & ".01" -> 02.03.02.03.01 | C51: SOLADO f'c=100 kg/cm2, e=10 cm | D51: m2 | I51: =+SUM(I52) -> 4.15 | J51: =I51*E50 -> 4.15
E52: 1 | F52: =F29 -> area | G52: =G29 -> 4.1548 | I52: =+ROUND(PRODUCT(E52:H52),2) -> 4.15
B54: =$B$20 & ".04" -> 02.03.02.04 | C54: SUMINISTRO E INSTALACION DE TUBERIAS | E54: =E21 -> 1
B55: =$B$54 & ".01" -> 02.03.02.04.01 | C55: SUMINISTRO E INSTALACION DE TUBERÍA DE PVC SAL Ø 2" | D55: m | E55: 1 | F55: 1.5 | I55: =+ROUND(PRODUCT(E55:H55),2) -> 1.5 | J55: =I55*E54 -> 1.5
B57: =$B$54 & ".02" -> 02.03.02.04.02 | C57: SUMINISTRO E INSTALACION DE TUBERÍA DE PVC SAL Ø 4" | D57: und | E57: 1 | F57: 2 | I57: =+ROUND(PRODUCT(E57:H57),2) -> 2 | J57: =I57*E54 -> 2
B59: =$B$20 & ".05" -> 02.03.02.05 | C59: SUMINISTRO E INSTALACION DE BIODIGESTOR | E59: =E54 -> 1
B60: =$B$59 & ".01" -> 02.03.02.05.01 | C60: SUMINISTRO E INSTALACION DE TUBERÍA DE BIODIGESTOR Y ACCESORIOS (1300L) | D60: und | E60: 1 | I60: =+ROUND(PRODUCT(E60:H60),2) -> 1 | J60: =I60*E59 -> 1
B62: 02.03.03 | C62: CAJA DE REGISTRO DE LODOS (0.80 x 0.80 m)
B63: =$B$62 & ".01" -> 02.03.03.01 | C63: TRABAJOS PRELIMINARES | E63: =E59 -> 1
B64: =$B$63 & ".01" -> 02.03.03.01.01 | C64: LIMPIEZA DE TERRENO MANUAL | D64: m2 | I64: =+SUM(I65:I65) -> 0.64 | J64: =I64*E63 -> 0.64
E65: 1 | F65: 0.8 | G65: 0.8 | I65: =+ROUND(PRODUCT(E65:H65),2) -> 0.64
B67: =$B$63 & ".02" -> 02.03.03.01.02 | C67: TRAZO Y REPLANTEO PRELIMINAR PARA ESTRUCTURAS | D67: m2 | I67: =+SUM(I68) -> 0.64 | J67: =I67*E63 -> 0.64
...

Sheet Metrado Acero
A1: PLANILLA DE METRADOS DEL SISTEMA DE SANEAMIENTO
A2: "CREACION DEL SERVICIO DE AGUA POTABLE RURAL Y CREACION DEL SERVICIO DE ALCANTARILLADO U OTRAS FORMAS DE DISPOSICION SANITARIA DE EXCRETAS EN EL SECTOR NUEVA ESPERANZA DE LA CC.NN. BAJO PITUCUNA DISTRITO DE RIO NEGRO, PROVINCIA DE SATIPO, DEPARTAMENTO DE JUNIN"
A3: PLANILLA DE METRADO ACERO
A4: DESCRIPCION | D4: ELEMENTO | J4: Ø (Pulg.) | K4: CANTIDAD | L4: N° DE ELEMENTOS | M4: LONG. DEL ELEMENTO (m) | N4: LONGITUD (m)
N5: 1/4" | O5: 3/8" | P5: 1/2" | Q5: 5/8" | R5: 3/4" | S5: 1"
A6: CASETA | B6: ZAPATAS Y COLUMNAS | C6: Acero Vertical frontal - Columna frontal
G7: 0.05
F8: 2.8 | J8: 3/8" | K8: 4 | L8: 4 | M8: =SUM(E6:H10) -> 2.95 | N8: =IF(+$J8=N$5,+$K8*$L8*$M8,0) -> 0 | O8: =IF(+$J8=O$5,+$K8*$L8*$M8,0) -> 47.2 | P8: =IF(+$J8=P$5,+$K8*$L8*$M8,0) -> 0 | Q8: =IF(+$J8=Q$5,+$K8*$L8*$M8,0) -> 0 | R8: =IF(+$J8=R$5,+$K8*$L8*$M8,0) -> 0 | S8: =IF(+$J8=S$5,+$K8*$L8*$M8,0) -> 0
F10: 0.1
C11: Acero Vertical frontal - Columna posterior | G11: 0.05
F13: 3.2 | J13: 3/8" | K13: 4 | L13: 4 | M13: =SUM(E11:G15) -> 3.35 | N13: =IF(+$J13=N$5,+$K13*$L13*$M13,0) -> 0 | O13: =IF(+$J13=O$5,+$K13*$L13*$M13,0) -> 53.6 | P13: =IF(+$J13=P$5,+$K13*$L13*$M13,0) -> 0 | Q13: =IF(+$J13=Q$5,+$K13*$L13*$M13,0) -> 0 | R13: =IF(+$J13=R$5,+$K13*$L13*$M13,0) -> 0 | S13: =IF(+$J13=S$5,+$K13*$L13*$M13,0) -> 0
F15: 0.1
C16: Estribos de Columnas frontal
E17: 0.05
H18: 0.12 | J18: 1/4" | K18: 18 | L18: 5 | M18: =SUM(E16:H20)*2 -> 0.58 | N18: =IF(+$J18=N$5,+$K18*$L18*$M18,0) -> 52.2 | O18: =IF(+$J18=O$5,+$K18*$L18*$M18,0) -> 0 | P18: =IF(+$J18=P$5,+$K18*$L18*$M18,0) -> 0 | Q18: =IF(+$J18=Q$5,+$K18*$L18*$M18,0) -> 0 | R18: =IF(+$J18=R$5,+$K18*$L18*$M18,0) -> 0 | S18: =IF(+$J18=S$5,+$K18*$L18*$M18,0) -> 0
F20: 0.12
C21: Estribos de Columnas posterior
E22: 0.05
H23: 0.12 | J23: 1/4" | K23: 20 | L23: 5 | M23: =SUM(E21:H25)*2 -> 0.58 | N23: =IF(+$J23=N$5,+$K23*$L23*$M23,0) -> 58 | O23: =IF(+$J23=O$5,+$K23*$L23*$M23,0) -> 0 | P23: =IF(+$J23=P$5,+$K23*$L23*$M23,0) -> 0 | Q23: =IF(+$J23=Q$5,+$K23*$L23*$M23,0) -> 0 | R23: =IF(+$J23=R$5,+$K23*$L23*$M23,0) -> 0 | S23: =IF(+$J23=S$5,+$K23*$L23*$M23,0) -> 0
F25: 0.12
C26: Columnas - Acero Vertical | G26: 0.46
E28: 0.15 | J28: 3/8" | K28: 3 | L28: 17 | M28: =SUM(E26:I30) -> 0.61 | N28: =IF(+$J28=N$5,+$K28*$L28*$M28,0) -> 0 | O28: =IF(+$J28=O$5,+$K28*$L28*$M28,0) -> 31.11 | P28: =IF(+$J28=P$5,+$K28*$L28*$M28,0) -> 0 | Q28: =IF(+$J28=Q$5,+$K28*$L28*$M28,0) -> 0 | R28: =IF(+$J28=R$5,+$K28*$L28*$M28,0) -> 0 | S28: =IF(+$J28=S$5,+$K28*$L28*$M28,0) -> 0
B31: VIGAS | C31: Eje 1-1, 2-2(A-B)- Acero Horizontal
G32: 5.02
J33: 3/8" | K33: 4 | L33: 2 | M33: =SUM(E32:I35) -> 5.12 | N33: =IF(+$J33=N$5,+$K33*$L33*$M33,0) -> 0 | O33: =IF(+$J33=O$5,+$K33*$L33*$M33,0) -> 40.96 | P33: =IF(+$J33=P$5,+$K33*$L33*$M33,0) -> 0 | Q33: =IF(+$J33=Q$5,+$K33*$L33*$M33,0) -> 0 | R33: =IF(+$J33=R$5,+$K33*$L33*$M33,0) -> 0 | S33: =IF(+$J33=S$5,+$K33*$L33*$M33,0) -> 0
E34: 0.05 | I34: 0.05
C36: Eje A-A, B-B, C-C, D-D (1-2)- Acero Horizontal
G37: 1.57
J38: 3/8" | K38: 4 | L38: 4 | M38: =SUM(D37:I40) -> 1.67 | N38: =IF(+$J38=N$5,+$K38*$L38*$M38,0) -> 0 | O38: =IF(+$J38=O$5,+$K38*$L38*$M38,0) -> 26.72 | P38: =IF(+$J38=P$5,+$K38*$L38*$M38,0) -> 0 | Q38: =IF(+$J38=Q$4,+$K38*$L38*$M38,0) -> 0 | R38: =IF(+$J38=R$4,+$K38*$L38*$M38,0) -> 0 | S38: =IF(+$J38=S$4,+$K38*$L38*$M38,0) -> 0
E39: 0.05 | I39: 0.05
C41: Estribo 1-1, 2-2 (A-B)- Acero Vertical | G41: 0.12
E42: 0.1
F43: 0.15 | H43: 0.12 | J43: 1/4" | K43: 37 | L43: 2 | M43: =SUM(E41:H45) -> 0.61 | N43: =IF(+$J43=N$5,+$K43*$L43*$M43,0) -> 45.14 | O43: =IF(+$J43=O$5,+$K43*$L43*$M43,0) -> 0 | P43: =IF(+$J43=P$5,+$K43*$L43*$M43,0) -> 0 | Q43: =IF(+$J43=Q$5,+$K43*$L43*$M43,0) -> 0 | R43: =IF(+$J43=R$5,+$K43*$L43*$M43,0) -> 0 | S43: =IF(+$J43=S$5,+$K43*$L43*$M43,0) -> 0
G45: 0.12
C46: Estribo A-A, B-B, C-C, D-D (1-2)- Acero Vertical
E47: 0.05
H48: 0.12 | J48: 1/4" | K48: 11 | L48: 4 | M48: =SUM(E46:H50)*2 -> 0.58 | N48: =IF(+$J48=N$5,+$K48*$L48*$M48,0) -> 25.52 | O48: =IF(+$J48=O$5,+$K48*$L48*$M48,0) -> 0 | P48: =IF(+$J48=P$5,+$K48*$L48*$M48,0) -> 0 | Q48: =IF(+$J48=Q$5,+$K48*$L48*$M48,0) -> 0 | R48: =IF(+$J48=R$5,+$K48*$L48*$M48,0) -> 0 | S48: =IF(+$J48=S$5,+$K48*$L48*$M48,0) -> 0
F50: 0.12
J51: SUB TOTAL (m) | N51: =SUM(N6:N50) -> 180.86 | O51: =SUM(O6:O50) -> 199.59 | P51: =SUM(P6:P50) -> 0 | Q51: =SUM(Q6:Q50) -> 0 | R51: =SUM(R6:R50) -> 0 | S51: =SUM(S6:S50) -> 0
J52: PESO POR DIAMETRO VARILLA (kg/m) | N52: 0.222 | O52: 0.56 | P52: 0.994 | Q52: 1.552 | R52: 2.235 | S52: 3.973
...

Sheet Acero
A1: MEJORAMIENTO Y AMPLIACIÓN DEL SERVICIO DE AGUA POTABLE E INSTALACIÓN DEL SERVICIO DE DISPOSICIÓN SANITARIA DE EXCRETAS EN EL CENTRO POBLADO JOSÉ GÁLVEZ, DISTRITO DE MAZAMARI - SATIPO - JUNÍN.”
A2: ESTRUCTURAS: Metrado Auxiliar de Acero | T2: UBS-BAÑOS DIGNOS
A4: N° de Partida | B4: Descripción del elemento estructural | C4: Diseño de Acero en el elemento estructural | K4: Diámetro de varilla | L4: Longitud por diseño (Inc. Traslape) | M4: Repeticiones del diseño | N4: Cant. elem. estructurales | O4: LONGITUD POR DIAMETRO DE VARILLA EN METROS LINEALES
O5: 1/4 | P5: 3/8 | Q5: 1/2 | R5: 5/8 | S5: 3/4 | T5: 1
A6: 02.02.04.01.03 | B6: ACERO CORRUGADO fy=4200 kg/cm2 GRADO 60
B8: Transversal | K8: 3/8 | L8: 0.25 | M8: 3 | N8: 1 | P8: 0.75
B9: Longitudinal | K9: 3/8 | L9: 0.25 | M9: 3 | N9: 1 | P9: 0.75
B10: Peso en kilogramos por metro lineal | O10: 0.25 | P10: 0.56 | Q10: 0.99 | R10: 1.55 | S10: 2.24 | T10: 3.97
B11: Longitud total por diámetro, en metros lineales | O11: 0 | P11: 1.5 | Q11: 0 | R11: 0 | S11: 0 | T11: 0
B12: Total en kilogramos por diámetro | O12: 0 | P12: 0.84 | Q12: 0 | R12: 0 | S12: 0 | T12: 0
B13: Nº Varillas | O13: 0 | P13: 0.17 | Q13: 0 | R13: 0 | S13: 0 | T13: 0
B14: Total en kilogramos | O14: 0.84
A15: 02.02.04.02.03 | B15: ACERO CORRUGADO fy=4200 kg/cm2 GRADO 60
B17: Eje A - A: Longitudinal | K17: 3/8 | L17: 3 | M17: 4 | N17: 2 | P17: 24
B18: estribos | K18: 1/4 | L18: 0.54 | M18: 22 | N18: 2 | O18: 23.76
B19: Eje C - C: Longitudinal | K19: 3/8 | L19: 3.8 | M19: 4 | N19: 2 | P19: 30.4
B20: estribos | K20: 1/4 | L20: 0.54 | M20: 27 | N20: 2 | O20: 29.16
B22: Peso en kilogramos por metro lineal | O22: 0.25 | P22: 0.56 | Q22: 0.99 | R22: 1.55 | S22: 2.24 | T22: 3.97
B23: Longitud total por diámetro, en metros lineales | O23: 52.92 | P23: 54.4 | Q23: 0 | R23: 0 | S23: 0 | T23: 0
B24: Total en kilogramos por diámetro | O24: 13.23 | P24: 30.46 | Q24: 0 | R24: 0 | S24: 0 | T24: 0
B25: Nº Varillas | O25: 5.88 | P25: 6.05 | Q25: 0 | R25: 0 | S25: 0 | T25: 0
B26: Total en kilogramos | O26: 43.69
A27: 02.02.04.03.03 | B27: ACERO CORRUGADO fy=4200 kg/cm2 GRADO 60
B29: Eje 1 - 1: Longitudinal | K29: 3/8 | L29: 3.3 | M29: 2 | N29: 1 | P29: 6.6
B30: estribos | K30: 1/4 | L30: 0.2 | M30: 11 | N30: 1 | O30: 2.2
B31: Eje A - A: Longitudinal | K31: 3/8 | L31: 2.3 | M31: 2 | N31: 1 | P31: 4.6
B32: estribos | K32: 1/4 | L32: 0.2 | M32: 16 | N32: 1 | O32: 3.2
B33: Eje 3 - 3: Longitudinal | K33: 3/8 | L33: 3.3 | M33: 2 | N33: 1 | P33: 6.6
B34: estribos | K34: 1/4 | L34: 0.2 | M34: 16 | N34: 1 | O34: 3.2
B35: Eje C - C: Longitudinal | K35: 3/8 | L35: 2.3 | M35: 2 | N35: 1 | P35: 4.6
B36: estribos | K36: 1/4 | L36: 0.2 | M36: 11 | N36: 1 | O36: 2.2
B38: Peso en kilogramos por metro lineal | O38: 0.25 | P38: 0.56 | Q38: 0.99 | R38: 1.55 | S38: 2.24 | T38: 3.97
B39: Longitud total por diámetro, en metros lineales | O39: 10.8 | P39: 22.4 | Q39: 0 | R39: 0 | S39: 0 | T39: 0
B40: Total en kilogramos por diámetro | O40: 2.7 | P40: 12.54 | Q40: 0 | R40: 0 | S40: 0 | T40: 0
B41: Nº Varillas | O41: 1.2 | P41: 2.49 | Q41: 0 | R41: 0 | S41: 0 | T41: 0
B42: Total en kilogramos | O42: 15.24
A43: 02.02.04.04.03 | B43: ACERO CORRUGADO fy=4200 kg/cm2 GRADO 60
B45: Longitudinal | K45: 3/8 | L45: 2.4 | M45: 1 | N45: 7 | P45: 16.8
B46: Transversal | K46: 3/8 | L46: 1.9 | M46: 1 | N46: 9 | P46: 17.1
B47: Peso en kilogramos por metro lineal | O47: 0.25 | P47: 0.56 | Q47: 0.99 | R47: 1.55 | S47: 2.24 | T47: 3.97
...
